Workbook

Sheet อ่านก่อน
B1: แบบจำลองการเงิน Angel Round — SPADA / OneManOS
B2: NextWaver.Net Co., Ltd. · เอกสาร SPADA-DOC-FUND-003 ฉบับ 1.1 (ฉบับนักลงทุน) · วันที่ออก: [ใส่วันที่ส่ง]
B4: วัตถุประสงค์ | C4: แสดงกระแสเงินสด 24 เดือน ผลของเงื่อนไขเงินกู้แปลงสภาพต่อสัดส่วนหุ้น และความไวต่อสมมติฐานสำคัญ เพื่อให้ผู้ลงทุนทดลองปรับตัวเลขเองได้
B5: วิธีใช้ | C5: แก้เฉพาะช่องที่เป็นตัวเลขสีน้ำเงินบนพื้นเหลืองในชีต 'สมมติฐาน' เท่านั้น ช่องสีดำเป็นสูตร ช่องสีเขียวเป็นการดึงค่าจากชีตอื่น ทุกชีตล็อกสูตรไว้ (ไม่มีรหัสผ่าน เพื่อป้องกันการพิมพ์ทับโดยไม่ตั้งใจ ไม่ใช่มาตรการความปลอดภัย)
B6: หน่วย | C6: จำนวนเงินเป็นบาท อัตราส่วนเป็นร้อยละ เดือนที่ 1 = เดือนที่ได้รับงวดที่ 1
B7: ชีตในไฟล์ | C7: สรุป · สมมติฐาน · กระแสเงินสด (24 เดือน) · การแปลงสภาพ (ทั้งเพดานแบบ pre-money และ post-money) · ความไว (10 สถานการณ์)
B8: ข้อจำกัดสำคัญ | C8: 1) ตัวเลขทั้งหมดเป็นสมมติฐานเพื่อการวางแผน ไม่ใช่การรับประกันผลลัพธ์ ไม่ใช่คำเสนอขายหลักทรัพย์ ไม่ใช่คำแนะนำทางการเงินหรือกฎหมาย
C9: 2) ค่า pen-test และฮาร์ดแวร์ต้นแบบเป็นประมาณการ ยังไม่มีใบเสนอราคา ดูผลกระทบในชีต 'ความไว'
C10: 3) ยังไม่มีผู้ใช้จริงและยังไม่มีรายได้ แบบจำลองนี้ไม่มีประมาณการรายได้ เป็นแบบจำลองกระแสเงินสดและการแปลงสภาพเท่านั้น
C11: 4) สัญญาเงินกู้แปลงสภาพต้องร่างโดยทนายไทย ผลคำนวณในไฟล์นี้ใช้นิยามที่ระบุในชีตสมมติฐาน ซึ่งต้องตรงกับสัญญาฉบับจริง
C12: 5) ยังไม่รวมภาษีหัก ณ ที่จ่ายของดอกเบี้ย และค่าธรรมเนียมทางกฎหมายของฝ่ายนักลงทุน
C13: 6) การแปลงสภาพต้องผ่านมติผู้ถือหุ้นและการเพิ่มทุนตามกฎหมายบริษัทจำกัด
B15: สัญลักษณ์สี | C15: ตัวเลขสีน้ำเงินบนพื้นเหลือง = ช่องกรอก
C16: สีดำ = สูตรคำนวณ
C17: สีเขียว = ดึงค่าจากชีตอื่น

Sheet สรุป
B1: สรุปสำหรับการเจรจา
B2: หน้านี้ดึงตัวเลขจากชีตอื่นอัตโนมัติ · ใช้เปิดคู่กับการหารือ
B4: ตัวเลขหลัก
B5: เงินที่เสนอทั้งรอบ (บาท) | C5: =สมมติฐาน!C10 -> 3000000
B6: งวดที่ 1 (บาท) | C6: =สมมติฐาน!C11 -> 2000000
B7: งวดที่ 2 (บาท) | C7: =สมมติฐาน!C12 -> 1000000
B8: ค่าใช้จ่ายประจำต่อเดือน (บาท) | C8: =สมมติฐาน!C21 -> 150000
B9: ค่าใช้จ่ายก้อนใหญ่รวม (บาท) | C9: =สมมติฐาน!C30 -> 960000
B10: อยู่ได้กี่เดือน ถ้าปลดงวดที่ 2 (เดือน) | C10: =กระแสเงินสด!F33 -> 13
B11: อยู่ได้กี่เดือน ถ้าได้เฉพาะงวดที่ 1 (เดือน) | C11: =ความไว!J7 -> 8
B12: เดือนแรกที่เงินติดลบ (ปลดงวดที่ 2) | C12: =กระแสเงินสด!F32 -> 14
B13: เงินสดสิ้นเดือน 6 ก่อนงวดที่ 2 (บาท) | C13: =กระแสเงินสด!F36 -> 380000
B14: เงินที่ต้องเพิ่มเพื่อไม่ติดลบตลอด 18 เดือน (บาท) | C14: =กระแสเงินสด!F35 -> 660000
B15: ยอดที่นำไปแปลงสภาพ (เงินต้น + ดอกเบี้ย) (บาท) | C15: =การแปลงสภาพ!E10 -> 3165000
B16: สัดส่วนนักลงทุนหลังแปลงสภาพ (ตามนิยามเพดานที่เลือก) | C16: =การแปลงสภาพ!C23 -> 0.17423617
B17: สัดส่วนที่ผู้ถือหุ้นเดิมเหลือ | C17: =การแปลงสภาพ!C27 -> 0.82576383
B18: ข้อไหนมีผลบังคับ (เพดานหรือส่วนลด) ที่มูลค่ารอบถัดไปตามสมมติฐาน | C18: =การแปลงสภาพ!C17 -> เพดานมูลค่า
B20: เงื่อนไขปลดงวดที่ 2 (เขียนลงสัญญา)
B21: • รายงานการทดสอบเจาะระบบจากผู้ตรวจอิสระที่ระบุชื่อในสัญญาออกแล้ว
B22: • ช่องโหว่ระดับ Critical และ High ได้รับการแก้ไข พร้อมหนังสือยืนยันผลการทดสอบซ้ำจากผู้ตรวจ
B23: • มีผู้ใช้จริงอย่างน้อย 10 ราย บนระบบที่เปิดใช้งาน (นิยาม "ผู้ใช้จริง" ระบุในสัญญา)
B24: • ส่งรายงานความคืบหน้าให้นักลงทุนครบทุกไตรมาส
B25: • นักลงทุนโอนงวดที่ 2 ภายใน 10 วันทำการหลังผู้ตรวจอิสระออกหนังสือยืนยันเงื่อนไข
B27: วัดผลทั้งรอบ
B28: • มีธุรกิจที่จ่ายเงินจริงอย่างน้อย 5 ราย ภายในเดือนที่ 12
B29: • ถ้าไม่ถึง แปลว่าโมเดลรายได้ผิด ไม่ใช่เงินไม่พอ — และบริษัทจะเปลี่ยนแผน ไม่ใช่ขอเงินเพิ่ม
B31: แบบจำลองนี้เป็นสมมติฐานเพื่อการวางแผน ไม่ใช่คำแนะนำทางการเงินหรือกฎหมาย ไม่ใช่คำเสนอขายหลักทรัพย์

Sheet สมมติฐาน
B1: สมมติฐาน (ช่องกรอกทั้งหมดอยู่ที่ชีตนี้)
B2: แก้เฉพาะตัวเลขสีน้ำเงินบนพื้นเหลือง · ทุกจำนวนเงินเป็นบาท · ทุกอัตราส่วนเป็นร้อยละ
B9: 1 · การระดมทุน
B10: เงินที่เสนอทั้งรอบ (บาท) | C10: 3000000 | E10: ยอดที่เสนอกับนักลงทุน
B11: งวดที่ 1 (บาท) | C11: 2000000 | E11: โอนหลังลงนามสัญญา
B12: งวดที่ 2 (บาท) | C12: =C10-C11 -> 1000000 | E12: ยอดรวมลบงวดที่ 1 · โอนเมื่อผ่านเงื่อนไขปลดงวดที่ 2
B13: เดือนที่ได้รับงวดที่ 1 | C13: 1 | E13: 1 = เดือนแรกของแบบจำลอง
B14: เดือนที่ได้รับงวดที่ 2 | C14: 7 | E14: หลังผ่านเงื่อนไขและโอนภายใน 10 วันทำการ (ดูชีตสรุป)
B15: เงินสดตั้งต้นในบริษัท (บาท) | C15: 0 | E15: ใส่ยอดจริง ณ วันที่ส่งเอกสาร
B17: 2 · ค่าใช้จ่ายประจำเดือน
B18: ค่าแรงทีม (รวมผู้ก่อตั้ง) | C18: 145000 | E18: ต้องตรงกับงบของบริษัท
B19: ค่าโครงสร้างพื้นฐาน (คลาวด์) | C19: 3000 | E19: โหนดไทย + สิงคโปร์ ตามประมาณการ
B20: ค่าดำเนินการอื่น | C20: 2000 | E20: เครื่องมือ ค่าธรรมเนียม เบ็ดเตล็ด
B21: รวมค่าใช้จ่ายต่อเดือน (บาท) | C21: =SUM(C18:C20) -> 150000
B22: อัตราค่าใช้จ่ายเพิ่มขึ้นต่อเดือน | C22: 0 | E22: ใส่ 2% ถ้าคาดว่าจะจ้างเพิ่มระหว่างทาง
B24: 3 · ค่าใช้จ่ายก้อนใหญ่ (จ่ายครั้งเดียว)
B25: รายการ | C25: จำนวนเงิน (บาท) | D25: เดือนที่จ่าย | E25: หมายเหตุ
B26: กฎหมาย · โอนสิทธิ์ IP · จดทะเบียน | C26: 120000 | D26: 1 | E26: ดำเนินการก่อนลงนามสัญญาลงทุน
B27: Pen-test รอบที่ 1 | C27: 450000 | D27: 2 | E27: ประมาณการ ยังไม่มีใบเสนอราคา ช่วงราคาที่ประเมินไว้ 450,000–900,000 บาท ดูชีตความไว
B28: Retest หลังแก้ไข | C28: 150000 | D28: 6 | E28: ต้องเสร็จก่อนปลดงวดที่ 2 (ใช้ยืนยันการแก้ช่องโหว่ Critical/High) ควรรวมในสัญญาผู้ทดสอบตั้งแต่แรก
B29: ฮาร์ดแวร์ Setbox ชุดต้นแบบ | C29: 240000 | D29: 9 | E29: 2–3 ชุดสำหรับชุมชนนำร่อง ราคายังไม่สรุป รอใบเสนอราคา
B30: รวมค่าใช้จ่ายก้อนใหญ่ (บาท) | C30: =SUM(C26:C29) -> 960000
B32: 4 · เงื่อนไขเงินกู้แปลงสภาพ
B33: จำนวนหุ้นปัจจุบันของบริษัท | C33: 100000 | E33: จำนวนหุ้นตัวอย่าง จะแทนด้วยจำนวนหุ้นจริงตาม บอจ.5 · สัดส่วนที่คำนวณไม่ขึ้นกับค่านี้
B34: เพดานมูลค่า valuation cap (บาท) | C34: 15000000
B35: นิยามเพดาน (1 = pre-money, 2 = post-money) | C35: 1 | E35: 1: สัดส่วน = ยอดแปลง ÷ (ยอดแปลง + เพดาน) · 2: สัดส่วน = ยอดแปลง ÷ เพดาน (ต้องตรงกับสัญญา)
B36: ส่วนลดจากราคารอบถัดไป | C36: 0.2
B37: ดอกเบี้ยต่อปี (คงที่ สะสม ไม่จ่ายเป็นเงินสด) | C37: 0.03 | E37: คิดจากวันที่เบิกจริงของแต่ละงวด · ภาษีหัก ณ ที่จ่ายยังไม่รวม
B38: เดือนที่แปลงสภาพ/ครบอายุสัญญา (นับจากเดือนที่ 1) | C38: 24 | E38: 24 = อายุสัญญา 24 เดือน
B39: มูลค่าก่อนเงินของรอบถัดไป (บาท) | C39: 40000000 | E39: สมมติฐานเพื่อทดสอบว่าเพดานหรือส่วนลดจะมีผลบังคับ ไม่ใช่การคาดการณ์มูลค่า
B41: ข้อจำกัดของแบบจำลองนี้
B42: • ตัวเลขทั้งหมดเป็นสมมติฐานเพื่อการวางแผน ไม่ใช่ใบเสนอราคาหรือคำแนะนำทางการเงิน
B43: • สัญญาเงินกู้แปลงสภาพในไทยต้องให้ทนายไทยร่าง
B44: • การแปลงสภาพต้องผ่านมติผู้ถือหุ้นและการเพิ่มทุนตามกฎหมายบริษัทจำกัด
B45: • ยังไม่รวมภาษีหัก ณ ที่จ่ายของดอกเบี้ย และค่าธรรมเนียมทางกฎหมายของฝ่ายนักลงทุน

Sheet กระแสเงินสด
B1: กระแสเงินสด 24 เดือน
B2: ทุกช่องเป็นสูตร · แก้ค่าได้ที่ชีตสมมติฐานเท่านั้น
B4: เดือนที่ | C4: เงินสดต้นงวด | D4: เงินลงทุนเข้า | E4: ค่าแรง | F4: คลาวด์ | G4: อื่นๆ | H4: ก้อนใหญ่ | I4: รวมจ่าย | J4: เงินสดปลายงวด | K4: สถานะ | L4: ตัวช่วย (ติดลบ=1)
B5: 1 | C5: =สมมติฐาน!$C$15 -> 0 | D5: =IF($B5=สมมติฐาน!$C$13,สมมติฐาน!$C$11,0)+IF($B5=สมมติฐาน!$C$14,สมมติฐาน!$C$12,0) -> 2000000 | E5: =สมมติฐาน!$C$18*(1+สมมติฐาน!$C$22)^($B5-1) -> 145000 | F5: =สมมติฐาน!$C$19*(1+สมมติฐาน!$C$22)^($B5-1) -> 3000 | G5: =สมมติฐาน!$C$20*(1+สมมติฐาน!$C$22)^($B5-1) -> 2000 | H5: =SUMIF(สมมติฐาน!$D$26:$D$29,$B5,สมมติฐาน!$C$26:$C$29) -> 120000 | I5: =SUM(E5:H5) -> 270000 | J5: =C5+D5-I5 -> 1730000 | K5: =IF(J5<0,"เงินหมด",IF(J5<สมมติฐาน!$C$21*2,"เหลือน้อย","ปกติ")) -> ปกติ | L5: =IF(J5<0,1,0) -> 0
B6: 2 | C6: =J5 -> 1730000 | D6: =IF($B6=สมมติฐาน!$C$13,สมมติฐาน!$C$11,0)+IF($B6=สมมติฐาน!$C$14,สมมติฐาน!$C$12,0) -> 0 | E6: =สมมติฐาน!$C$18*(1+สมมติฐาน!$C$22)^($B6-1) -> 145000 | F6: =สมมติฐาน!$C$19*(1+สมมติฐาน!$C$22)^($B6-1) -> 3000 | G6: =สมมติฐาน!$C$20*(1+สมมติฐาน!$C$22)^($B6-1) -> 2000 | H6: =SUMIF(สมมติฐาน!$D$26:$D$29,$B6,สมมติฐาน!$C$26:$C$29) -> 450000 | I6: =SUM(E6:H6) -> 600000 | J6: =C6+D6-I6 -> 1130000 | K6: =IF(J6<0,"เงินหมด",IF(J6<สมมติฐาน!$C$21*2,"เหลือน้อย","ปกติ")) -> ปกติ | L6: =IF(J6<0,1,0) -> 0
B7: 3 | C7: =J6 -> 1130000 | D7: =IF($B7=สมมติฐาน!$C$13,สมมติฐาน!$C$11,0)+IF($B7=สมมติฐาน!$C$14,สมมติฐาน!$C$12,0) -> 0 | E7: =สมมติฐาน!$C$18*(1+สมมติฐาน!$C$22)^($B7-1) -> 145000 | F7: =สมมติฐาน!$C$19*(1+สมมติฐาน!$C$22)^($B7-1) -> 3000 | G7: =สมมติฐาน!$C$20*(1+สมมติฐาน!$C$22)^($B7-1) -> 2000 | H7: =SUMIF(สมมติฐาน!$D$26:$D$29,$B7,สมมติฐาน!$C$26:$C$29) -> 0 | I7: =SUM(E7:H7) -> 150000 | J7: =C7+D7-I7 -> 980000 | K7: =IF(J7<0,"เงินหมด",IF(J7<สมมติฐาน!$C$21*2,"เหลือน้อย","ปกติ")) -> ปกติ | L7: =IF(J7<0,1,0) -> 0
B8: 4 | C8: =J7 -> 980000 | D8: =IF($B8=สมมติฐาน!$C$13,สมมติฐาน!$C$11,0)+IF($B8=สมมติฐาน!$C$14,สมมติฐาน!$C$12,0) -> 0 | E8: =สมมติฐาน!$C$18*(1+สมมติฐาน!$C$22)^($B8-1) -> 145000 | F8: =สมมติฐาน!$C$19*(1+สมมติฐาน!$C$22)^($B8-1) -> 3000 | G8: =สมมติฐาน!$C$20*(1+สมมติฐาน!$C$22)^($B8-1) -> 2000 | H8: =SUMIF(สมมติฐาน!$D$26:$D$29,$B8,สมมติฐาน!$C$26:$C$29) -> 0 | I8: =SUM(E8:H8) -> 150000 | J8: =C8+D8-I8 -> 830000 | K8: =IF(J8<0,"เงินหมด",IF(J8<สมมติฐาน!$C$21*2,"เหลือน้อย","ปกติ")) -> ปกติ | L8: =IF(J8<0,1,0) -> 0
B9: 5 | C9: =J8 -> 830000 | D9: =IF($B9=สมมติฐาน!$C$13,สมมติฐาน!$C$11,0)+IF($B9=สมมติฐาน!$C$14,สมมติฐาน!$C$12,0) -> 0 | E9: =สมมติฐาน!$C$18*(1+สมมติฐาน!$C$22)^($B9-1) -> 145000 | F9: =สมมติฐาน!$C$19*(1+สมมติฐาน!$C$22)^($B9-1) -> 3000 | G9: =สมมติฐาน!$C$20*(1+สมมติฐาน!$C$22)^($B9-1) -> 2000 | H9: =SUMIF(สมมติฐาน!$D$26:$D$29,$B9,สมมติฐาน!$C$26:$C$29) -> 0 | I9: =SUM(E9:H9) -> 150000 | J9: =C9+D9-I9 -> 680000 | K9: =IF(J9<0,"เงินหมด",IF(J9<สมมติฐาน!$C$21*2,"เหลือน้อย","ปกติ")) -> ปกติ | L9: =IF(J9<0,1,0) -> 0
B10: 6 | C10: =J9 -> 680000 | D10: =IF($B10=สมมติฐาน!$C$13,สมมติฐาน!$C$11,0)+IF($B10=สมมติฐาน!$C$14,สมมติฐาน!$C$12,0) -> 0 | E10: =สมมติฐาน!$C$18*(1+สมมติฐาน!$C$22)^($B10-1) -> 145000 | F10: =สมมติฐาน!$C$19*(1+สมมติฐาน!$C$22)^($B10-1) -> 3000 | G10: =สมมติฐาน!$C$20*(1+สมมติฐาน!$C$22)^($B10-1) -> 2000 | H10: =SUMIF(สมมติฐาน!$D$26:$D$29,$B10,สมมติฐาน!$C$26:$C$29) -> 150000 | I10: =SUM(E10:H10) -> 300000 | J10: =C10+D10-I10 -> 380000 | K10: =IF(J10<0,"เงินหมด",IF(J10<สมมติฐาน!$C$21*2,"เหลือน้อย","ปกติ")) -> ปกติ | L10: =IF(J10<0,1,0) -> 0
B11: 7 | C11: =J10 -> 380000 | D11: =IF($B11=สมมติฐาน!$C$13,สมมติฐาน!$C$11,0)+IF($B11=สมมติฐาน!$C$14,สมมติฐาน!$C$12,0) -> 1000000 | E11: =สมมติฐาน!$C$18*(1+สมมติฐาน!$C$22)^($B11-1) -> 145000 | F11: =สมมติฐาน!$C$19*(1+สมมติฐาน!$C$22)^($B11-1) -> 3000 | G11: =สมมติฐาน!$C$20*(1+สมมติฐาน!$C$22)^($B11-1) -> 2000 | H11: =SUMIF(สมมติฐาน!$D$26:$D$29,$B11,สมมติฐาน!$C$26:$C$29) -> 0 | I11: =SUM(E11:H11) -> 150000 | J11: =C11+D11-I11 -> 1230000 | K11: =IF(J11<0,"เงินหมด",IF(J11<สมมติฐาน!$C$21*2,"เหลือน้อย","ปกติ")) -> ปกติ | L11: =IF(J11<0,1,0) -> 0
B12: 8 | C12: =J11 -> 1230000 | D12: =IF($B12=สมมติฐาน!$C$13,สมมติฐาน!$C$11,0)+IF($B12=สมมติฐาน!$C$14,สมมติฐาน!$C$12,0) -> 0 | E12: =สมมติฐาน!$C$18*(1+สมมติฐาน!$C$22)^($B12-1) -> 145000 | F12: =สมมติฐาน!$C$19*(1+สมมติฐาน!$C$22)^($B12-1) -> 3000 | G12: =สมมติฐาน!$C$20*(1+สมมติฐาน!$C$22)^($B12-1) -> 2000 | H12: =SUMIF(สมมติฐาน!$D$26:$D$29,$B12,สมมติฐาน!$C$26:$C$29) -> 0 | I12: =SUM(E12:H12) -> 150000 | J12: =C12+D12-I12 -> 1080000 | K12: =IF(J12<0,"เงินหมด",IF(J12<สมมติฐาน!$C$21*2,"เหลือน้อย","ปกติ")) -> ปกติ | L12: =IF(J12<0,1,0) -> 0
B13: 9 | C13: =J12 -> 1080000 | D13: =IF($B13=สมมติฐาน!$C$13,สมมติฐาน!$C$11,0)+IF($B13=สมมติฐาน!$C$14,สมมติฐาน!$C$12,0) -> 0 | E13: =สมมติฐาน!$C$18*(1+สมมติฐาน!$C$22)^($B13-1) -> 145000 | F13: =สมมติฐาน!$C$19*(1+สมมติฐาน!$C$22)^($B13-1) -> 3000 | G13: =สมมติฐาน!$C$20*(1+สมมติฐาน!$C$22)^($B13-1) -> 2000 | H13: =SUMIF(สมมติฐาน!$D$26:$D$29,$B13,สมมติฐาน!$C$26:$C$29) -> 240000 | I13: =SUM(E13:H13) -> 390000 | J13: =C13+D13-I13 -> 690000 | K13: =IF(J13<0,"เงินหมด",IF(J13<สมมติฐาน!$C$21*2,"เหลือน้อย","ปกติ")) -> ปกติ | L13: =IF(J13<0,1,0) -> 0
B14: 10 | C14: =J13 -> 690000 | D14: =IF($B14=สมมติฐาน!$C$13,สมมติฐาน!$C$11,0)+IF($B14=สมมติฐาน!$C$14,สมมติฐาน!$C$12,0) -> 0 | E14: =สมมติฐาน!$C$18*(1+สมมติฐาน!$C$22)^($B14-1) -> 145000 | F14: =สมมติฐาน!$C$19*(1+สมมติฐาน!$C$22)^($B14-1) -> 3000 | G14: =สมมติฐาน!$C$20*(1+สมมติฐาน!$C$22)^($B14-1) -> 2000 | H14: =SUMIF(สมมติฐาน!$D$26:$D$29,$B14,สมมติฐาน!$C$26:$C$29) -> 0 | I14: =SUM(E14:H14) -> 150000 | J14: =C14+D14-I14 -> 540000 | K14: =IF(J14<0,"เงินหมด",IF(J14<สมมติฐาน!$C$21*2,"เหลือน้อย","ปกติ")) -> ปกติ | L14: =IF(J14<0,1,0) -> 0
B15: 11 | C15: =J14 -> 540000 | D15: =IF($B15=สมมติฐาน!$C$13,สมมติฐาน!$C$11,0)+IF($B15=สมมติฐาน!$C$14,สมมติฐาน!$C$12,0) -> 0 | E15: =สมมติฐาน!$C$18*(1+สมมติฐาน!$C$22)^($B15-1) -> 145000 | F15: =สมมติฐาน!$C$19*(1+สมมติฐาน!$C$22)^($B15-1) -> 3000 | G15: =สมมติฐาน!$C$20*(1+สมมติฐาน!$C$22)^($B15-1) -> 2000 | H15: =SUMIF(สมมติฐาน!$D$26:$D$29,$B15,สมมติฐาน!$C$26:$C$29) -> 0 | I15: =SUM(E15:H15) -> 150000 | J15: =C15+D15-I15 -> 390000 | K15: =IF(J15<0,"เงินหมด",IF(J15<สมมติฐาน!$C$21*2,"เหลือน้อย","ปกติ")) -> ปกติ | L15: =IF(J15<0,1,0) -> 0
B16: 12 | C16: =J15 -> 390000 | D16: =IF($B16=สมมติฐาน!$C$13,สมมติฐาน!$C$11,0)+IF($B16=สมมติฐาน!$C$14,สมมติฐาน!$C$12,0) -> 0 | E16: =สมมติฐาน!$C$18*(1+สมมติฐาน!$C$22)^($B16-1) -> 145000 | F16: =สมมติฐาน!$C$19*(1+สมมติฐาน!$C$22)^($B16-1) -> 3000 | G16: =สมมติฐาน!$C$20*(1+สมมติฐาน!$C$22)^($B16-1) -> 2000 | H16: =SUMIF(สมมติฐาน!$D$26:$D$29,$B16,สมมติฐาน!$C$26:$C$29) -> 0 | I16: =SUM(E16:H16) -> 150000 | J16: =C16+D16-I16 -> 240000 | K16: =IF(J16<0,"เงินหมด",IF(J16<สมมติฐาน!$C$21*2,"เหลือน้อย","ปกติ")) -> เหลือน้อย | L16: =IF(J16<0,1,0) -> 0
B17: 13 | C17: =J16 -> 240000 | D17: =IF($B17=สมมติฐาน!$C$13,สมมติฐาน!$C$11,0)+IF($B17=สมมติฐาน!$C$14,สมมติฐาน!$C$12,0) -> 0 | E17: =สมมติฐาน!$C$18*(1+สมมติฐาน!$C$22)^($B17-1) -> 145000 | F17: =สมมติฐาน!$C$19*(1+สมมติฐาน!$C$22)^($B17-1) -> 3000 | G17: =สมมติฐาน!$C$20*(1+สมมติฐาน!$C$22)^($B17-1) -> 2000 | H17: =SUMIF(สมมติฐาน!$D$26:$D$29,$B17,สมมติฐาน!$C$26:$C$29) -> 0 | I17: =SUM(E17:H17) -> 150000 | J17: =C17+D17-I17 -> 90000 | K17: =IF(J17<0,"เงินหมด",IF(J17<สมมติฐาน!$C$21*2,"เหลือน้อย","ปกติ")) -> เหลือน้อย | L17: =IF(J17<0,1,0) -> 0
... B28: 24 | C28: =J27 -> -1410000 | D28: =IF($B28=สมมติฐาน!$C$13,สมมติฐาน!$C$11,0)+IF($B28=สมมติฐาน!$C$14,สมมติฐาน!$C$12,0) -> 0 | E28: =สมมติฐาน!$C$18*(1+สมมติฐาน!$C$22)^($B28-1) -> 145000 | F28: =สมมติฐาน!$C$19*(1+สมมติฐาน!$C$22)^($B28-1) -> 3000 | G28: =สมมติฐาน!$C$20*(1+สมมติฐาน!$C$22)^($B28-1) -> 2000 | H28: =SUMIF(สมมติฐาน!$D$26:$D$29,$B28,สมมติฐาน!$C$26:$C$29) -> 0 | I28: =SUM(E28:H28) -> 150000 | J28: =C28+D28-I28 -> -1560000 | K28: =IF(J28<0,"เงินหมด",IF(J28<สมมติฐาน!$C$21*2,"เหลือน้อย","ปกติ")) -> เงินหมด | L28: =IF(J28<0,1,0) -> 1
B31: สรุปกระแสเงินสด
B32: เดือนแรกที่เงินสดติดลบ (0 = ไม่ติดลบใน 24 เดือน) | F32: =IFERROR(MATCH(1,L5:L28,0),0) -> 14
B33: จำนวนเดือนที่เงินยังไม่หมด (runway) | F33: =IF(F32=0,24,F32-1) -> 13
B34: เงินสดต่ำสุดใน 18 เดือนแรก (บาท) | F34: =MIN(J5:J22) -> -660000
B35: เงินที่ต้องเพิ่มเพื่อให้ไม่ติดลบตลอด 18 เดือน (บาท) | F35: =MAX(0,-F34) -> 660000
B36: เงินสดสิ้นเดือนที่ 6 (ก่อนงวดที่ 2) (บาท) | F36: =J10 -> 380000

Sheet การแปลงสภาพ
B1: การแปลงสภาพเป็นหุ้น และสัดส่วนที่นักลงทุนได้
B2: แก้เพดาน ส่วนลด ดอกเบี้ย และนิยามเพดานได้ที่ชีตสมมติฐาน แถว 34–39
B4: ก. ยอดที่จะแปลงสภาพ (ดอกเบี้ยคิดจากวันที่เบิกจริงของแต่ละงวด)
B5: รายการ | C5: งวดที่ 1 | D5: งวดที่ 2 | E5: รวม
B6: เงินต้น (บาท) | C6: =สมมติฐาน!C11 -> 2000000 | D6: =สมมติฐาน!C12 -> 1000000 | E6: =C6+D6 -> 3000000
B7: เดือนที่เบิก | C7: =สมมติฐาน!C13 -> 1 | D7: =สมมติฐาน!C14 -> 7
B8: จำนวนเดือนที่ดอกเบี้ยสะสม | C8: =MAX(0,สมมติฐาน!$C$38-(C7-1)) -> 24 | D8: =MAX(0,สมมติฐาน!$C$38-(D7-1)) -> 18
B9: ดอกเบี้ยสะสม (บาท) | C9: =C6*สมมติฐาน!$C$37*C8/12 -> 120000 | D9: =D6*สมมติฐาน!$C$37*D8/12 -> 45000 | E9: =C9+D9 -> 165000
B10: ยอดที่นำไปแปลงเป็นหุ้น (บาท) | C10: =C6+C9 -> 2120000 | D10: =D6+D9 -> 1045000 | E10: =E6+E9 -> 3165000
B12: ข. ราคาต่อหุ้น: เพดานกับส่วนลด อันไหนใช้จริง (คิดแบบ pre-money)
B13: ราคาต่อหุ้นจากเพดานมูลค่า (บาท) | C13: =สมมติฐาน!C34/สมมติฐาน!C33 -> 150
B14: ราคาต่อหุ้นรอบถัดไป ก่อนส่วนลด (บาท) | C14: =สมมติฐาน!C39/สมมติฐาน!C33 -> 400
B15: ราคาต่อหุ้นรอบถัดไป หลังส่วนลด (บาท) | C15: =C14*(1-สมมติฐาน!C36) -> 320
B16: ราคาที่ใช้จริง (ต่ำกว่าชนะ) (บาท) | C16: =MIN(C13,C15) -> 150
B17: ข้อไหนมีผลบังคับ | C17: =IF(C13<=C15,"เพดานมูลค่า","ส่วนลด") -> เพดานมูลค่า
B18: ส่วนลดจะมีผลเมื่อมูลค่าก่อนเงินของรอบถัดไปต่ำกว่า (บาท) | C18: =สมมติฐาน!C34/(1-สมมติฐาน!C36) -> 18750000
B20: ค. ผลต่อสัดส่วนผู้ถือหุ้น (ตามนิยามเพดานที่เลือกในสมมติฐาน)
B21: สัดส่วนนักลงทุน ถ้าใช้เพดาน | C21: =IF(สมมติฐาน!C35=1,E10/(E10+สมมติฐาน!C34),E10/สมมติฐาน!C34) -> 0.17423617
B22: สัดส่วนนักลงทุน ถ้าใช้ส่วนลด | C22: =E10/(E10+สมมติฐาน!C39*(1-สมมติฐาน!C36)) -> 0.090004266
B23: สัดส่วนที่ใช้จริง (ค่าที่ให้นักลงทุนมากกว่า) | C23: =MAX(C21,C22) -> 0.17423617
B24: จำนวนหุ้นที่นักลงทุนจะได้ | C24: =C23/(1-C23)*สมมติฐาน!C33 -> 21100
B25: จำนวนหุ้นเดิม | C25: =สมมติฐาน!C33 -> 100000
B26: จำนวนหุ้นรวมหลังแปลงสภาพ | C26: =C24+C25 -> 121100
B27: สัดส่วนที่ผู้ถือหุ้นเดิมเหลือ | C27: =1-C23 -> 0.82576383
B28: ตรวจสอบ: หุ้นที่นักลงทุนได้ ÷ หุ้นรวม (ต้องเท่ากับสัดส่วนที่ใช้จริง) | C28: =C24/C26 -> 0.17423617
B30: ง. ความไวของเพดานมูลค่า (ยอดแปลงตามข้อ ก)
B31: เพดานมูลค่า (บาท) | C31: สัดส่วนนักลงทุน ถ้าเพดานเป็น pre-money | D31: สัดส่วนนักลงทุน ถ้าเพดานเป็น post-money | E31: เพดาน post-money ที่ให้สัดส่วนเท่ากับ pre-money นี้ (บาท)
B32: 8000000 | C32: =$E$10/($E$10+B32) -> 0.28347515 | D32: =IF(B32>0,$E$10/B32,0) -> 0.395625 | E32: =$E$10+B32 -> 11165000
B33: 10000000 | C33: =$E$10/($E$10+B33) -> 0.24041018 | D33: =IF(B33>0,$E$10/B33,0) -> 0.3165 | E33: =$E$10+B33 -> 13165000
B34: 12000000 | C34: =$E$10/($E$10+B34) -> 0.20870425 | D34: =IF(B34>0,$E$10/B34,0) -> 0.26375 | E34: =$E$10+B34 -> 15165000
B35: 15000000 | C35: =$E$10/($E$10+B35) -> 0.17423617 | D35: =IF(B35>0,$E$10/B35,0) -> 0.211 | E35: =$E$10+B35 -> 18165000
B36: 18000000 | C36: =$E$10/($E$10+B36) -> 0.14953933 | D36: =IF(B36>0,$E$10/B36,0) -> 0.17583333 | E36: =$E$10+B36 -> 21165000
B37: 20000000 | C37: =$E$10/($E$10+B37) -> 0.13662853 | D37: =IF(B37>0,$E$10/B37,0) -> 0.15825 | E37: =$E$10+B37 -> 23165000
B38: 25000000 | C38: =$E$10/($E$10+B38) -> 0.11237351 | D38: =IF(B38>0,$E$10/B38,0) -> 0.1266 | E38: =$E$10+B38 -> 28165000
B39: 30000000 | C39: =$E$10/($E$10+B39) -> 0.095431931 | D39: =IF(B39>0,$E$10/B39,0) -> 0.1055 | E39: =$E$10+B39 -> 33165000
B41: จ. ความไวของดอกเบี้ย (ที่เพดานและนิยามที่เลือก)
B42: ดอกเบี้ยต่อปี | C42: ยอดแปลง (บาท) | D42: สัดส่วนนักลงทุน
B43: 0 | C43: =$E$6+B43*($C$6*$C$8+$D$6*$D$8)/12 -> 3000000 | D43: =IF(สมมติฐาน!$C$35=1,C43/(C43+สมมติฐาน!$C$34),C43/สมมติฐาน!$C$34) -> 0.16666667
B44: 0.03 | C44: =$E$6+B44*($C$6*$C$8+$D$6*$D$8)/12 -> 3165000 | D44: =IF(สมมติฐาน!$C$35=1,C44/(C44+สมมติฐาน!$C$34),C44/สมมติฐาน!$C$34) -> 0.17423617
B45: 0.05 | C45: =$E$6+B45*($C$6*$C$8+$D$6*$D$8)/12 -> 3275000 | D45: =IF(สมมติฐาน!$C$35=1,C45/(C45+สมมติฐาน!$C$34),C45/สมมติฐาน!$C$34) -> 0.17920657
...

Sheet ความไว
B1: ความไวของกระแสเงินสดต่อสมมติฐานสำคัญ (10 สถานการณ์)
B2: แถวแรกดึงค่าจากชีตสมมติฐาน แถวอื่นเปลี่ยนเฉพาะช่องสีน้ำเงิน ที่เหลือเท่ากับแถวฐาน · เงินสดรายเดือนคำนวณด้วยสูตรแบบปิดรูป (ผลเท่ากับชีตกระแสเงินสดในแถวฐาน)
B5: สถานการณ์ | C5: งวดที่ 1 (บาท) | D5: งวดที่ 2 (บาท) | E5: เดือนที่ได้งวดที่ 2 | F5: Pen-test (บาท) | G5: ฮาร์ดแวร์ (บาท) | H5: ค่าใช้จ่ายเพิ่มต่อเดือน | I5: เดือนแรกที่ติดลบ (0=ไม่ติดลบ) | J5: runway (เดือน) | K5: เงินสดสิ้นเดือน 6 | L5: เงินสดสิ้นเดือน 7 | M5: เงินสดสิ้นเดือน 8 | N5: เงินสดต่ำสุด 18 เดือน | O5: เงินที่ต้องเพิ่มเพื่อครบ 18 เดือน
B6: ฐาน (ตามสมมติฐาน) | C6: =สมมติฐาน!C11 -> 2000000 | D6: =สมมติฐาน!C12 -> 1000000 | E6: =สมมติฐาน!C14 -> 7 | F6: =สมมติฐาน!C27 -> 450000 | G6: =สมมติฐาน!C29 -> 240000 | H6: =สมมติฐาน!C22 -> 0 | I6: =IFERROR(MATCH(1,C34:Z34,0),0) -> 14 | J6: =IF(I6=0,24,I6-1) -> 13 | K6: =INDEX(C20:Z20,6) -> 380000 | L6: =INDEX(C20:Z20,7) -> 1230000 | M6: =INDEX(C20:Z20,8) -> 1080000 | N6: =MIN(C20:T20) -> -660000 | O6: =MAX(0,-N6) -> 660000
B7: ได้เฉพาะงวดที่ 1 (ไม่ปลดงวดที่ 2) | C7: =$C$6 -> 2000000 | D7: 0 | E7: =$E$6 -> 7 | F7: =$F$6 -> 450000 | G7: =$G$6 -> 240000 | H7: =$H$6 -> 0 | I7: =IFERROR(MATCH(1,C35:Z35,0),0) -> 9 | J7: =IF(I7=0,24,I7-1) -> 8 | K7: =INDEX(C21:Z21,6) -> 380000 | L7: =INDEX(C21:Z21,7) -> 230000 | M7: =INDEX(C21:Z21,8) -> 80000 | N7: =MIN(C21:T21) -> -1660000 | O7: =MAX(0,-N7) -> 1660000
B8: งวดที่ 2 ล่าช้า 1 เดือน | C8: =$C$6 -> 2000000 | D8: =$D$6 -> 1000000 | E8: =$E$6+1 -> 8 | F8: =$F$6 -> 450000 | G8: =$G$6 -> 240000 | H8: =$H$6 -> 0 | I8: =IFERROR(MATCH(1,C36:Z36,0),0) -> 14 | J8: =IF(I8=0,24,I8-1) -> 13 | K8: =INDEX(C22:Z22,6) -> 380000 | L8: =INDEX(C22:Z22,7) -> 230000 | M8: =INDEX(C22:Z22,8) -> 1080000 | N8: =MIN(C22:T22) -> -660000 | O8: =MAX(0,-N8) -> 660000
B9: งวดที่ 2 ล่าช้า 2 เดือน | C9: =$C$6 -> 2000000 | D9: =$D$6 -> 1000000 | E9: =$E$6+2 -> 9 | F9: =$F$6 -> 450000 | G9: =$G$6 -> 240000 | H9: =$H$6 -> 0 | I9: =IFERROR(MATCH(1,C37:Z37,0),0) -> 14 | J9: =IF(I9=0,24,I9-1) -> 13 | K9: =INDEX(C23:Z23,6) -> 380000 | L9: =INDEX(C23:Z23,7) -> 230000 | M9: =INDEX(C23:Z23,8) -> 80000 | N9: =MIN(C23:T23) -> -660000 | O9: =MAX(0,-N9) -> 660000
B10: Pen-test 700,000 | C10: =$C$6 -> 2000000 | D10: =$D$6 -> 1000000 | E10: =$E$6 -> 7 | F10: 700000 | G10: =$G$6 -> 240000 | H10: =$H$6 -> 0 | I10: =IFERROR(MATCH(1,C38:Z38,0),0) -> 12 | J10: =IF(I10=0,24,I10-1) -> 11 | K10: =INDEX(C24:Z24,6) -> 130000 | L10: =INDEX(C24:Z24,7) -> 980000 | M10: =INDEX(C24:Z24,8) -> 830000 | N10: =MIN(C24:T24) -> -910000 | O10: =MAX(0,-N10) -> 910000
B11: Pen-test 830,000 (เงินสดเดือน 6 ≈ 0) | C11: =$C$6 -> 2000000 | D11: =$D$6 -> 1000000 | E11: =$E$6 -> 7 | F11: 830000 | G11: =$G$6 -> 240000 | H11: =$H$6 -> 0 | I11: =IFERROR(MATCH(1,C39:Z39,0),0) -> 12 | J11: =IF(I11=0,24,I11-1) -> 11 | K11: =INDEX(C25:Z25,6) -> 0 | L11: =INDEX(C25:Z25,7) -> 850000 | M11: =INDEX(C25:Z25,8) -> 700000 | N11: =MIN(C25:T25) -> -1040000 | O11: =MAX(0,-N11) -> 1040000
B12: Pen-test 900,000 | C12: =$C$6 -> 2000000 | D12: =$D$6 -> 1000000 | E12: =$E$6 -> 7 | F12: 900000 | G12: =$G$6 -> 240000 | H12: =$H$6 -> 0 | I12: =IFERROR(MATCH(1,C40:Z40,0),0) -> 6 | J12: =IF(I12=0,24,I12-1) -> 5 | K12: =INDEX(C26:Z26,6) -> -70000 | L12: =INDEX(C26:Z26,7) -> 780000 | M12: =INDEX(C26:Z26,8) -> 630000 | N12: =MIN(C26:T26) -> -1110000 | O12: =MAX(0,-N12) -> 1110000
B13: ค่าใช้จ่ายเพิ่ม 2% ต่อเดือน | C13: =$C$6 -> 2000000 | D13: =$D$6 -> 1000000 | E13: =$E$6 -> 7 | F13: =$F$6 -> 450000 | G13: =$G$6 -> 240000 | H13: 0.02 | I13: =IFERROR(MATCH(1,C41:Z41,0),0) -> 13 | J13: =IF(I13=0,24,I13-1) -> 12 | K13: =INDEX(C27:Z27,6) -> 333781.86 | L13: =INDEX(C27:Z27,7) -> 1164857.5 | M13: =INDEX(C27:Z27,8) -> 992554.64 | N13: =MIN(C27:T27) -> -1171846.9 | O13: =MAX(0,-N13) -> 1171846.9
B14: ฮาร์ดแวร์ 400,000 | C14: =$C$6 -> 2000000 | D14: =$D$6 -> 1000000 | E14: =$E$6 -> 7 | F14: =$F$6 -> 450000 | G14: 400000 | H14: =$H$6 -> 0 | I14: =IFERROR(MATCH(1,C42:Z42,0),0) -> 13 | J14: =IF(I14=0,24,I14-1) -> 12 | K14: =INDEX(C28:Z28,6) -> 380000 | L14: =INDEX(C28:Z28,7) -> 1230000 | M14: =INDEX(C28:Z28,8) -> 1080000 | N14: =MIN(C28:T28) -> -820000 | O14: =MAX(0,-N14) -> 820000
B15: Pen-test 900,000 + งวดที่ 2 ล่าช้า 1 เดือน | C15: =$C$6 -> 2000000 | D15: =$D$6 -> 1000000 | E15: =$E$6+1 -> 8 | F15: 900000 | G15: =$G$6 -> 240000 | H15: =$H$6 -> 0 | I15: =IFERROR(MATCH(1,C43:Z43,0),0) -> 6 | J15: =IF(I15=0,24,I15-1) -> 5 | K15: =INDEX(C29:Z29,6) -> -70000 | L15: =INDEX(C29:Z29,7) -> -220000 | M15: =INDEX(C29:Z29,8) -> 630000 | N15: =MIN(C29:T29) -> -1110000 | O15: =MAX(0,-N15) -> 1110000
B17: หมายเหตุ: ทุกสถานการณ์ใช้ค่าอื่นเท่ากับแถวฐาน (ค่าใช้จ่ายรายเดือน ก้อนใหญ่อื่น เดือนที่จ่าย) · เดือนแรกที่ติดลบ = 0 หมายถึงไม่ติดลบใน 24 เดือน
B18: เงินสดปลายงวดรายเดือน (บาท)
B19: สถานการณ์ | C19: 1 | D19: 2 | E19: 3 | F19: 4 | G19: 5 | H19: 6 | I19: 7 | J19: 8 | K19: 9 | L19: 10 | M19: 11 | N19: 12 | O19: 13 | P19: 14 | Q19: 15 | R19: 16 | S19: 17 | T19: 18 | U19: 19 | V19: 20 | W19: 21 | X19: 22 | Y19: 23 | Z19: 24
B20: =B6 -> ฐาน (ตามสมมติฐาน) | C20: =สมมติฐาน!$C$15+$C6*(C$19>=สมมติฐาน!$C$13)+$D6*(C$19>=$E6)-IF($H6=0,สมมติฐาน!$C$21*C$19,สมมติฐาน!$C$21*((1+$H6)^C$19-1)/$H6)-(สมมติฐาน!$C$26*(C$19>=สมมติฐาน!$D$26)+$F6*(C$19>=สมมติฐาน!$D$27)+สมมติฐาน!$C$28*(C$19>=สมมติฐาน!$D$28)+$G6*(C$19>=สมมติฐาน!$D$29)) -> 1730000 | D20: =สมมติฐาน!$C$15+$C6*(D$19>=สมมติฐาน!$C$13)+$D6*(D$19>=$E6)-IF($H6=0,สมมติฐาน!$C$21*D$19,สมมติฐาน!$C$21*((1+$H6)^D$19-1)/$H6)-(สมมติฐาน!$C$26*(D$19>=สมมติฐาน!$D$26)+$F6*(D$19>=สมมติฐาน!$D$27)+สมมติฐาน!$C$28*(D$19>=สมมติฐาน!$D$28)+$G6*(D$19>=สมมติฐาน!$D$29)) -> 1130000 | E20: =สมมติฐาน!$C$15+$C6*(E$19>=สมมติฐาน!$C$13)+$D6*(E$19>=$E6)-IF($H6=0,สมมติฐาน!$C$21*E$19,สมมติฐาน!$C$21*((1+$H6)^E$19-1)/$H6)-(สมมติฐาน!$C$26*(E$19>=สมมติฐาน!$D$26)+$F6*(E$19>=สมมติฐาน!$D$27)+สมมติฐาน!$C$28*(E$19>=สมมติฐาน!$D$28)+$G6*(E$19>=สมมติฐาน!$D$29)) -> 980000 | F20: =สมมติฐาน!$C$15+$C6*(F$19>=สมมติฐาน!$C$13)+$D6*(F$19>=$E6)-IF($H6=0,สมมติฐาน!$C$21*F$19,สมมติฐาน!$C$21*((1+$H6)^F$19-1)/$H6)-(สมมติฐาน!$C$26*(F$19>=สมมติฐาน!$D$26)+$F6*(F$19>=สมมติฐาน!$D$27)+สมมติฐาน!$C$28*(F$19>=สมมติฐาน!$D$28)+$G6*(F$19>=สมมติฐาน!$D$29)) -> 830000 | G20: =สมมติฐาน!$C$15+$C6*(G$19>=สมมติฐาน!$C$13)+$D6*(G$19>=$E6)-IF($H6=0,สมมติฐาน!$C$21*G$19,สมมติฐาน!$C$21*((1+$H6)^G$19-1)/$H6)-(สมมติฐาน!$C$26*(G$19>=สมมติฐาน!$D$26)+$F6*(G$19>=สมมติฐาน!$D$27)+สมมติฐาน!$C$28*(G$19>=สมมติฐาน!$D$28)+$G6*(G$19>=สมมติฐาน!$D$29)) -> 680000 | H20: =สมมติฐาน!$C$15+$C6*(H$19>=สมมติฐาน!$C$13)+$D6*(H$19>=$E6)-IF($H6=0,สมมติฐาน!$C$21*H$19,สมมติฐาน!$C$21*((1+$H6)^H$19-1)/$H6)-(สมมติฐาน!$C$26*(H$19>=สมมติฐาน!$D$26)+$F6*(H$19>=สมมติฐาน!$D$27)+สมมติฐาน!$C$28*(H$19>=สมมติฐาน!$D$28)+$G6*(H$19>=สมมติฐาน!$D$29)) -> 380000 | I20: =สมมติฐาน!$C$15+$C6*(I$19>=สมมติฐาน!$C$13)+$D6*(I$19>=$E6)-IF($H6=0,สมมติฐาน!$C$21*I$19,สมมติฐาน!$C$21*((1+$H6)^I$19-1)/$H6)-(สมมติฐาน!$C$26*(I$19>=สมมติฐาน!$D$26)+$F6*(I$19>=สมมติฐาน!$D$27)+สมมติฐาน!$C$28*(I$19>=สมมติฐาน!$D$28)+$G6*(I$19>=สมมติฐาน!$D$29)) -> 1230000 | J20: =สมมติฐาน!$C$15+$C6*(J$19>=สมมติฐาน!$C$13)+$D6*(J$19>=$E6)-IF($H6=0,สมมติฐาน!$C$21*J$19,สมมติฐาน!$C$21*((1+$H6)^J$19-1)/$H6)-(สมมติฐาน!$C$26*(J$19>=สมมติฐาน!$D$26)+$F6*(J$19>=สมมติฐาน!$D$27)+สมมติฐาน!$C$28*(J$19>=สมมติฐาน!$D$28)+$G6*(J$19>=สมมติฐาน!$D$29)) -> 1080000 | ... Z20: =สมมติฐาน!$C$15+$C6*(Z$19>=สมมติฐาน!$C$13)+$D6*(Z$19>=$E6)-IF($H6=0,สมมติฐาน!$C$21*Z$19,สมมติฐาน!$C$21*((1+$H6)^Z$19-1)/$H6)-(สมมติฐาน!$C$26*(Z$19>=สมมติฐาน!$D$26)+$F6*(Z$19>=สมมติฐาน!$D$27)+สมมติฐาน!$C$28*(Z$19>=สมมติฐาน!$D$28)+$G6*(Z$19>=สมมติฐาน!$D$29)) -> -1560000
B21: =B7 -> ได้เฉพาะงวดที่ 1 (ไม่ปลดงวดที่ 2) | C21: =สมมติฐาน!$C$15+$C7*(C$19>=สมมติฐาน!$C$13)+$D7*(C$19>=$E7)-IF($H7=0,สมมติฐาน!$C$21*C$19,สมมติฐาน!$C$21*((1+$H7)^C$19-1)/$H7)-(สมมติฐาน!$C$26*(C$19>=สมมติฐาน!$D$26)+$F7*(C$19>=สมมติฐาน!$D$27)+สมมติฐาน!$C$28*(C$19>=สมมติฐาน!$D$28)+$G7*(C$19>=สมมติฐาน!$D$29)) -> 1730000 | D21: =สมมติฐาน!$C$15+$C7*(D$19>=สมมติฐาน!$C$13)+$D7*(D$19>=$E7)-IF($H7=0,สมมติฐาน!$C$21*D$19,สมมติฐาน!$C$21*((1+$H7)^D$19-1)/$H7)-(สมมติฐาน!$C$26*(D$19>=สมมติฐาน!$D$26)+$F7*(D$19>=สมมติฐาน!$D$27)+สมมติฐาน!$C$28*(D$19>=สมมติฐาน!$D$28)+$G7*(D$19>=สมมติฐาน!$D$29)) -> 1130000 | E21: =สมมติฐาน!$C$15+$C7*(E$19>=สมมติฐาน!$C$13)+$D7*(E$19>=$E7)-IF($H7=0,สมมติฐาน!$C$21*E$19,สมมติฐาน!$C$21*((1+$H7)^E$19-1)/$H7)-(สมมติฐาน!$C$26*(E$19>=สมมติฐาน!$D$26)+$F7*(E$19>=สมมติฐาน!$D$27)+สมมติฐาน!$C$28*(E$19>=สมมติฐาน!$D$28)+$G7*(E$19>=สมมติฐาน!$D$29)) -> 980000 | F21: =สมมติฐาน!$C$15+$C7*(F$19>=สมมติฐาน!$C$13)+$D7*(F$19>=$E7)-IF($H7=0,สมมติฐาน!$C$21*F$19,สมมติฐาน!$C$21*((1+$H7)^F$19-1)/$H7)-(สมมติฐาน!$C$26*(F$19>=สมมติฐาน!$D$26)+$F7*(F$19>=สมมติฐาน!$D$27)+สมมติฐาน!$C$28*(F$19>=สมมติฐาน!$D$28)+$G7*(F$19>=สมมติฐาน!$D$29)) -> 830000 | G21: =สมมติฐาน!$C$15+$C7*(G$19>=สมมติฐาน!$C$13)+$D7*(G$19>=$E7)-IF($H7=0,สมมติฐาน!$C$21*G$19,สมมติฐาน!$C$21*((1+$H7)^G$19-1)/$H7)-(สมมติฐาน!$C$26*(G$19>=สมมติฐาน!$D$26)+$F7*(G$19>=สมมติฐาน!$D$27)+สมมติฐาน!$C$28*(G$19>=สมมติฐาน!$D$28)+$G7*(G$19>=สมมติฐาน!$D$29)) -> 680000 | H21: =สมมติฐาน!$C$15+$C7*(H$19>=สมมติฐาน!$C$13)+$D7*(H$19>=$E7)-IF($H7=0,สมมติฐาน!$C$21*H$19,สมมติฐาน!$C$21*((1+$H7)^H$19-1)/$H7)-(สมมติฐาน!$C$26*(H$19>=สมมติฐาน!$D$26)+$F7*(H$19>=สมมติฐาน!$D$27)+สมมติฐาน!$C$28*(H$19>=สมมติฐาน!$D$28)+$G7*(H$19>=สมมติฐาน!$D$29)) -> 380000 | I21: =สมมติฐาน!$C$15+$C7*(I$19>=สมมติฐาน!$C$13)+$D7*(I$19>=$E7)-IF($H7=0,สมมติฐาน!$C$21*I$19,สมมติฐาน!$C$21*((1+$H7)^I$19-1)/$H7)-(สมมติฐาน!$C$26*(I$19>=สมมติฐาน!$D$26)+$F7*(I$19>=สมมติฐาน!$D$27)+สมมติฐาน!$C$28*(I$19>=สมมติฐาน!$D$28)+$G7*(I$19>=สมมติฐาน!$D$29)) -> 230000 | J21: =สมมติฐาน!$C$15+$C7*(J$19>=สมมติฐาน!$C$13)+$D7*(J$19>=$E7)-IF($H7=0,สมมติฐาน!$C$21*J$19,สมมติฐาน!$C$21*((1+$H7)^J$19-1)/$H7)-(สมมติฐาน!$C$26*(J$19>=สมมติฐาน!$D$26)+$F7*(J$19>=สมมติฐาน!$D$27)+สมมติฐาน!$C$28*(J$19>=สมมติฐาน!$D$28)+$G7*(J$19>=สมมติฐาน!$D$29)) -> 80000 | ... Z21: =สมมติฐาน!$C$15+$C7*(Z$19>=สมมติฐาน!$C$13)+$D7*(Z$19>=$E7)-IF($H7=0,สมมติฐาน!$C$21*Z$19,สมมติฐาน!$C$21*((1+$H7)^Z$19-1)/$H7)-(สมมติฐาน!$C$26*(Z$19>=สมมติฐาน!$D$26)+$F7*(Z$19>=สมมติฐาน!$D$27)+สมมติฐาน!$C$28*(Z$19>=สมมติฐาน!$D$28)+$G7*(Z$19>=สมมติฐาน!$D$29)) -> -2560000
B22: =B8 -> งวดที่ 2 ล่าช้า 1 เดือน | C22: =สมมติฐาน!$C$15+$C8*(C$19>=สมมติฐาน!$C$13)+$D8*(C$19>=$E8)-IF($H8=0,สมมติฐาน!$C$21*C$19,สมมติฐาน!$C$21*((1+$H8)^C$19-1)/$H8)-(สมมติฐาน!$C$26*(C$19>=สมมติฐาน!$D$26)+$F8*(C$19>=สมมติฐาน!$D$27)+สมมติฐาน!$C$28*(C$19>=สมมติฐาน!$D$28)+$G8*(C$19>=สมมติฐาน!$D$29)) -> 1730000 | D22: =สมมติฐาน!$C$15+$C8*(D$19>=สมมติฐาน!$C$13)+$D8*(D$19>=$E8)-IF($H8=0,สมมติฐาน!$C$21*D$19,สมมติฐาน!$C$21*((1+$H8)^D$19-1)/$H8)-(สมมติฐาน!$C$26*(D$19>=สมมติฐาน!$D$26)+$F8*(D$19>=สมมติฐาน!$D$27)+สมมติฐาน!$C$28*(D$19>=สมมติฐาน!$D$28)+$G8*(D$19>=สมมติฐาน!$D$29)) -> 1130000 | E22: =สมมติฐาน!$C$15+$C8*(E$19>=สมมติฐาน!$C$13)+$D8*(E$19>=$E8)-IF($H8=0,สมมติฐาน!$C$21*E$19,สมมติฐาน!$C$21*((1+$H8)^E$19-1)/$H8)-(สมมติฐาน!$C$26*(E$19>=สมมติฐาน!$D$26)+$F8*(E$19>=สมมติฐาน!$D$27)+สมมติฐาน!$C$28*(E$19>=สมมติฐาน!$D$28)+$G8*(E$19>=สมมติฐาน!$D$29)) -> 980000 | F22: =สมมติฐาน!$C$15+$C8*(F$19>=สมมติฐาน!$C$13)+$D8*(F$19>=$E8)-IF($H8=0,สมมติฐาน!$C$21*F$19,สมมติฐาน!$C$21*((1+$H8)^F$19-1)/$H8)-(สมมติฐาน!$C$26*(F$19>=สมมติฐาน!$D$26)+$F8*(F$19>=สมมติฐาน!$D$27)+สมมติฐาน!$C$28*(F$19>=สมมติฐาน!$D$28)+$G8*(F$19>=สมมติฐาน!$D$29)) -> 830000 | G22: =สมมติฐาน!$C$15+$C8*(G$19>=สมมติฐาน!$C$13)+$D8*(G$19>=$E8)-IF($H8=0,สมมติฐาน!$C$21*G$19,สมมติฐาน!$C$21*((1+$H8)^G$19-1)/$H8)-(สมมติฐาน!$C$26*(G$19>=สมมติฐาน!$D$26)+$F8*(G$19>=สมมติฐาน!$D$27)+สมมติฐาน!$C$28*(G$19>=สมมติฐาน!$D$28)+$G8*(G$19>=สมมติฐาน!$D$29)) -> 680000 | H22: =สมมติฐาน!$C$15+$C8*(H$19>=สมมติฐาน!$C$13)+$D8*(H$19>=$E8)-IF($H8=0,สมมติฐาน!$C$21*H$19,สมมติฐาน!$C$21*((1+$H8)^H$19-1)/$H8)-(สมมติฐาน!$C$26*(H$19>=สมมติฐาน!$D$26)+$F8*(H$19>=สมมติฐาน!$D$27)+สมมติฐาน!$C$28*(H$19>=สมมติฐาน!$D$28)+$G8*(H$19>=สมมติฐาน!$D$29)) -> 380000 | I22: =สมมติฐาน!$C$15+$C8*(I$19>=สมมติฐาน!$C$13)+$D8*(I$19>=$E8)-IF($H8=0,สมมติฐาน!$C$21*I$19,สมมติฐาน!$C$21*((1+$H8)^I$19-1)/$H8)-(สมมติฐาน!$C$26*(I$19>=สมมติฐาน!$D$26)+$F8*(I$19>=สมมติฐาน!$D$27)+สมมติฐาน!$C$28*(I$19>=สมมติฐาน!$D$28)+$G8*(I$19>=สมมติฐาน!$D$29)) -> 230000 | J22: =สมมติฐาน!$C$15+$C8*(J$19>=สมมติฐาน!$C$13)+$D8*(J$19>=$E8)-IF($H8=0,สมมติฐาน!$C$21*J$19,สมมติฐาน!$C$21*((1+$H8)^J$19-1)/$H8)-(สมมติฐาน!$C$26*(J$19>=สมมติฐาน!$D$26)+$F8*(J$19>=สมมติฐาน!$D$27)+สมมติฐาน!$C$28*(J$19>=สมมติฐาน!$D$28)+$G8*(J$19>=สมมติฐาน!$D$29)) -> 1080000 | ... Z22: =สมมติฐาน!$C$15+$C8*(Z$19>=สมมติฐาน!$C$13)+$D8*(Z$19>=$E8)-IF($H8=0,สมมติฐาน!$C$21*Z$19,สมมติฐาน!$C$21*((1+$H8)^Z$19-1)/$H8)-(สมมติฐาน!$C$26*(Z$19>=สมมติฐาน!$D$26)+$F8*(Z$19>=สมมติฐาน!$D$27)+สมมติฐาน!$C$28*(Z$19>=สมมติฐาน!$D$28)+$G8*(Z$19>=สมมติฐาน!$D$29)) -> -1560000
B23: =B9 -> งวดที่ 2 ล่าช้า 2 เดือน | C23: =สมมติฐาน!$C$15+$C9*(C$19>=สมมติฐาน!$C$13)+$D9*(C$19>=$E9)-IF($H9=0,สมมติฐาน!$C$21*C$19,สมมติฐาน!$C$21*((1+$H9)^C$19-1)/$H9)-(สมมติฐาน!$C$26*(C$19>=สมมติฐาน!$D$26)+$F9*(C$19>=สมมติฐาน!$D$27)+สมมติฐาน!$C$28*(C$19>=สมมติฐาน!$D$28)+$G9*(C$19>=สมมติฐาน!$D$29)) -> 1730000 | D23: =สมมติฐาน!$C$15+$C9*(D$19>=สมมติฐาน!$C$13)+$D9*(D$19>=$E9)-IF($H9=0,สมมติฐาน!$C$21*D$19,สมมติฐาน!$C$21*((1+$H9)^D$19-1)/$H9)-(สมมติฐาน!$C$26*(D$19>=สมมติฐาน!$D$26)+$F9*(D$19>=สมมติฐาน!$D$27)+สมมติฐาน!$C$28*(D$19>=สมมติฐาน!$D$28)+$G9*(D$19>=สมมติฐาน!$D$29)) -> 1130000 | E23: =สมมติฐาน!$C$15+$C9*(E$19>=สมมติฐาน!$C$13)+$D9*(E$19>=$E9)-IF($H9=0,สมมติฐาน!$C$21*E$19,สมมติฐาน!$C$21*((1+$H9)^E$19-1)/$H9)-(สมมติฐาน!$C$26*(E$19>=สมมติฐาน!$D$26)+$F9*(E$19>=สมมติฐาน!$D$27)+สมมติฐาน!$C$28*(E$19>=สมมติฐาน!$D$28)+$G9*(E$19>=สมมติฐาน!$D$29)) -> 980000 | F23: =สมมติฐาน!$C$15+$C9*(F$19>=สมมติฐาน!$C$13)+$D9*(F$19>=$E9)-IF($H9=0,สมมติฐาน!$C$21*F$19,สมมติฐาน!$C$21*((1+$H9)^F$19-1)/$H9)-(สมมติฐาน!$C$26*(F$19>=สมมติฐาน!$D$26)+$F9*(F$19>=สมมติฐาน!$D$27)+สมมติฐาน!$C$28*(F$19>=สมมติฐาน!$D$28)+$G9*(F$19>=สมมติฐาน!$D$29)) -> 830000 | G23: =สมมติฐาน!$C$15+$C9*(G$19>=สมมติฐาน!$C$13)+$D9*(G$19>=$E9)-IF($H9=0,สมมติฐาน!$C$21*G$19,สมมติฐาน!$C$21*((1+$H9)^G$19-1)/$H9)-(สมมติฐาน!$C$26*(G$19>=สมมติฐาน!$D$26)+$F9*(G$19>=สมมติฐาน!$D$27)+สมมติฐาน!$C$28*(G$19>=สมมติฐาน!$D$28)+$G9*(G$19>=สมมติฐาน!$D$29)) -> 680000 | H23: =สมมติฐาน!$C$15+$C9*(H$19>=สมมติฐาน!$C$13)+$D9*(H$19>=$E9)-IF($H9=0,สมมติฐาน!$C$21*H$19,สมมติฐาน!$C$21*((1+$H9)^H$19-1)/$H9)-(สมมติฐาน!$C$26*(H$19>=สมมติฐาน!$D$26)+$F9*(H$19>=สมมติฐาน!$D$27)+สมมติฐาน!$C$28*(H$19>=สมมติฐาน!$D$28)+$G9*(H$19>=สมมติฐาน!$D$29)) -> 380000 | I23: =สมมติฐาน!$C$15+$C9*(I$19>=สมมติฐาน!$C$13)+$D9*(I$19>=$E9)-IF($H9=0,สมมติฐาน!$C$21*I$19,สมมติฐาน!$C$21*((1+$H9)^I$19-1)/$H9)-(สมมติฐาน!$C$26*(I$19>=สมมติฐาน!$D$26)+$F9*(I$19>=สมมติฐาน!$D$27)+สมมติฐาน!$C$28*(I$19>=สมมติฐาน!$D$28)+$G9*(I$19>=สมมติฐาน!$D$29)) -> 230000 | J23: =สมมติฐาน!$C$15+$C9*(J$19>=สมมติฐาน!$C$13)+$D9*(J$19>=$E9)-IF($H9=0,สมมติฐาน!$C$21*J$19,สมมติฐาน!$C$21*((1+$H9)^J$19-1)/$H9)-(สมมติฐาน!$C$26*(J$19>=สมมติฐาน!$D$26)+$F9*(J$19>=สมมติฐาน!$D$27)+สมมติฐาน!$C$28*(J$19>=สมมติฐาน!$D$28)+$G9*(J$19>=สมมติฐาน!$D$29)) -> 80000 | ... Z23: =สมมติฐาน!$C$15+$C9*(Z$19>=สมมติฐาน!$C$13)+$D9*(Z$19>=$E9)-IF($H9=0,สมมติฐาน!$C$21*Z$19,สมมติฐาน!$C$21*((1+$H9)^Z$19-1)/$H9)-(สมมติฐาน!$C$26*(Z$19>=สมมติฐาน!$D$26)+$F9*(Z$19>=สมมติฐาน!$D$27)+สมมติฐาน!$C$28*(Z$19>=สมมติฐาน!$D$28)+$G9*(Z$19>=สมมติฐาน!$D$29)) -> -1560000
B24: =B10 -> Pen-test 700,000 | C24: =สมมติฐาน!$C$15+$C10*(C$19>=สมมติฐาน!$C$13)+$D10*(C$19>=$E10)-IF($H10=0,สมมติฐาน!$C$21*C$19,สมมติฐาน!$C$21*((1+$H10)^C$19-1)/$H10)-(สมมติฐาน!$C$26*(C$19>=สมมติฐาน!$D$26)+$F10*(C$19>=สมมติฐาน!$D$27)+สมมติฐาน!$C$28*(C$19>=สมมติฐาน!$D$28)+$G10*(C$19>=สมมติฐาน!$D$29)) -> 1730000 | D24: =สมมติฐาน!$C$15+$C10*(D$19>=สมมติฐาน!$C$13)+$D10*(D$19>=$E10)-IF($H10=0,สมมติฐาน!$C$21*D$19,สมมติฐาน!$C$21*((1+$H10)^D$19-1)/$H10)-(สมมติฐาน!$C$26*(D$19>=สมมติฐาน!$D$26)+$F10*(D$19>=สมมติฐาน!$D$27)+สมมติฐาน!$C$28*(D$19>=สมมติฐาน!$D$28)+$G10*(D$19>=สมมติฐาน!$D$29)) -> 880000 | E24: =สมมติฐาน!$C$15+$C10*(E$19>=สมมติฐาน!$C$13)+$D10*(E$19>=$E10)-IF($H10=0,สมมติฐาน!$C$21*E$19,สมมติฐาน!$C$21*((1+$H10)^E$19-1)/$H10)-(สมมติฐาน!$C$26*(E$19>=สมมติฐาน!$D$26)+$F10*(E$19>=สมมติฐาน!$D$27)+สมมติฐาน!$C$28*(E$19>=สมมติฐาน!$D$28)+$G10*(E$19>=สมมติฐาน!$D$29)) -> 730000 | F24: =สมมติฐาน!$C$15+$C10*(F$19>=สมมติฐาน!$C$13)+$D10*(F$19>=$E10)-IF($H10=0,สมมติฐาน!$C$21*F$19,สมมติฐาน!$C$21*((1+$H10)^F$19-1)/$H10)-(สมมติฐาน!$C$26*(F$19>=สมมติฐาน!$D$26)+$F10*(F$19>=สมมติฐาน!$D$27)+สมมติฐาน!$C$28*(F$19>=สมมติฐาน!$D$28)+$G10*(F$19>=สมมติฐาน!$D$29)) -> 580000 | G24: =สมมติฐาน!$C$15+$C10*(G$19>=สมมติฐาน!$C$13)+$D10*(G$19>=$E10)-IF($H10=0,สมมติฐาน!$C$21*G$19,สมมติฐาน!$C$21*((1+$H10)^G$19-1)/$H10)-(สมมติฐาน!$C$26*(G$19>=สมมติฐาน!$D$26)+$F10*(G$19>=สมมติฐาน!$D$27)+สมมติฐาน!$C$28*(G$19>=สมมติฐาน!$D$28)+$G10*(G$19>=สมมติฐาน!$D$29)) -> 430000 | H24: =สมมติฐาน!$C$15+$C10*(H$19>=สมมติฐาน!$C$13)+$D10*(H$19>=$E10)-IF($H10=0,สมมติฐาน!$C$21*H$19,สมมติฐาน!$C$21*((1+$H10)^H$19-1)/$H10)-(สมมติฐาน!$C$26*(H$19>=สมมติฐาน!$D$26)+$F10*(H$19>=สมมติฐาน!$D$27)+สมมติฐาน!$C$28*(H$19>=สมมติฐาน!$D$28)+$G10*(H$19>=สมมติฐาน!$D$29)) -> 130000 | I24: =สมมติฐาน!$C$15+$C10*(I$19>=สมมติฐาน!$C$13)+$D10*(I$19>=$E10)-IF($H10=0,สมมติฐาน!$C$21*I$19,สมมติฐาน!$C$21*((1+$H10)^I$19-1)/$H10)-(สมมติฐาน!$C$26*(I$19>=สมมติฐาน!$D$26)+$F10*(I$19>=สมมติฐาน!$D$27)+สมมติฐาน!$C$28*(I$19>=สมมติฐาน!$D$28)+$G10*(I$19>=สมมติฐาน!$D$29)) -> 980000 | J24: =สมมติฐาน!$C$15+$C10*(J$19>=สมมติฐาน!$C$13)+$D10*(J$19>=$E10)-IF($H10=0,สมมติฐาน!$C$21*J$19,สมมติฐาน!$C$21*((1+$H10)^J$19-1)/$H10)-(สมมติฐาน!$C$26*(J$19>=สมมติฐาน!$D$26)+$F10*(J$19>=สมมติฐาน!$D$27)+สมมติฐาน!$C$28*(J$19>=สมมติฐาน!$D$28)+$G10*(J$19>=สมมติฐาน!$D$29)) -> 830000 | ... Z24: =สมมติฐาน!$C$15+$C10*(Z$19>=สมมติฐาน!$C$13)+$D10*(Z$19>=$E10)-IF($H10=0,สมมติฐาน!$C$21*Z$19,สมมติฐาน!$C$21*((1+$H10)^Z$19-1)/$H10)-(สมมติฐาน!$C$26*(Z$19>=สมมติฐาน!$D$26)+$F10*(Z$19>=สมมติฐาน!$D$27)+สมมติฐาน!$C$28*(Z$19>=สมมติฐาน!$D$28)+$G10*(Z$19>=สมมติฐาน!$D$29)) -> -1810000
B25: =B11 -> Pen-test 830,000 (เงินสดเดือน 6 ≈ 0) | C25: =สมมติฐาน!$C$15+$C11*(C$19>=สมมติฐาน!$C$13)+$D11*(C$19>=$E11)-IF($H11=0,สมมติฐาน!$C$21*C$19,สมมติฐาน!$C$21*((1+$H11)^C$19-1)/$H11)-(สมมติฐาน!$C$26*(C$19>=สมมติฐาน!$D$26)+$F11*(C$19>=สมมติฐาน!$D$27)+สมมติฐาน!$C$28*(C$19>=สมมติฐาน!$D$28)+$G11*(C$19>=สมมติฐาน!$D$29)) -> 1730000 | D25: =สมมติฐาน!$C$15+$C11*(D$19>=สมมติฐาน!$C$13)+$D11*(D$19>=$E11)-IF($H11=0,สมมติฐาน!$C$21*D$19,สมมติฐาน!$C$21*((1+$H11)^D$19-1)/$H11)-(สมมติฐาน!$C$26*(D$19>=สมมติฐาน!$D$26)+$F11*(D$19>=สมมติฐาน!$D$27)+สมมติฐาน!$C$28*(D$19>=สมมติฐาน!$D$28)+$G11*(D$19>=สมมติฐาน!$D$29)) -> 750000 | E25: =สมมติฐาน!$C$15+$C11*(E$19>=สมมติฐาน!$C$13)+$D11*(E$19>=$E11)-IF($H11=0,สมมติฐาน!$C$21*E$19,สมมติฐาน!$C$21*((1+$H11)^E$19-1)/$H11)-(สมมติฐาน!$C$26*(E$19>=สมมติฐาน!$D$26)+$F11*(E$19>=สมมติฐาน!$D$27)+สมมติฐาน!$C$28*(E$19>=สมมติฐาน!$D$28)+$G11*(E$19>=สมมติฐาน!$D$29)) -> 600000 | F25: =สมมติฐาน!$C$15+$C11*(F$19>=สมมติฐาน!$C$13)+$D11*(F$19>=$E11)-IF($H11=0,สมมติฐาน!$C$21*F$19,สมมติฐาน!$C$21*((1+$H11)^F$19-1)/$H11)-(สมมติฐาน!$C$26*(F$19>=สมมติฐาน!$D$26)+$F11*(F$19>=สมมติฐาน!$D$27)+สมมติฐาน!$C$28*(F$19>=สมมติฐาน!$D$28)+$G11*(F$19>=สมมติฐาน!$D$29)) -> 450000 | G25: =สมมติฐาน!$C$15+$C11*(G$19>=สมมติฐาน!$C$13)+$D11*(G$19>=$E11)-IF($H11=0,สมมติฐาน!$C$21*G$19,สมมติฐาน!$C$21*((1+$H11)^G$19-1)/$H11)-(สมมติฐาน!$C$26*(G$19>=สมมติฐาน!$D$26)+$F11*(G$19>=สมมติฐาน!$D$27)+สมมติฐาน!$C$28*(G$19>=สมมติฐาน!$D$28)+$G11*(G$19>=สมมติฐาน!$D$29)) -> 300000 | H25: =สมมติฐาน!$C$15+$C11*(H$19>=สมมติฐาน!$C$13)+$D11*(H$19>=$E11)-IF($H11=0,สมมติฐาน!$C$21*H$19,สมมติฐาน!$C$21*((1+$H11)^H$19-1)/$H11)-(สมมติฐาน!$C$26*(H$19>=สมมติฐาน!$D$26)+$F11*(H$19>=สมมติฐาน!$D$27)+สมมติฐาน!$C$28*(H$19>=สมมติฐาน!$D$28)+$G11*(H$19>=สมมติฐาน!$D$29)) -> 0 | I25: =สมมติฐาน!$C$15+$C11*(I$19>=สมมติฐาน!$C$13)+$D11*(I$19>=$E11)-IF($H11=0,สมมติฐาน!$C$21*I$19,สมมติฐาน!$C$21*((1+$H11)^I$19-1)/$H11)-(สมมติฐาน!$C$26*(I$19>=สมมติฐาน!$D$26)+$F11*(I$19>=สมมติฐาน!$D$27)+สมมติฐาน!$C$28*(I$19>=สมมติฐาน!$D$28)+$G11*(I$19>=สมมติฐาน!$D$29)) -> 850000 | J25: =สมมติฐาน!$C$15+$C11*(J$19>=สมมติฐาน!$C$13)+$D11*(J$19>=$E11)-IF($H11=0,สมมติฐาน!$C$21*J$19,สมมติฐาน!$C$21*((1+$H11)^J$19-1)/$H11)-(สมมติฐาน!$C$26*(J$19>=สมมติฐาน!$D$26)+$F11*(J$19>=สมมติฐาน!$D$27)+สมมติฐาน!$C$28*(J$19>=สมมติฐาน!$D$28)+$G11*(J$19>=สมมติฐาน!$D$29)) -> 700000 | ... Z25: =สมมติฐาน!$C$15+$C11*(Z$19>=สมมติฐาน!$C$13)+$D11*(Z$19>=$E11)-IF($H11=0,สมมติฐาน!$C$21*Z$19,สมมติฐาน!$C$21*((1+$H11)^Z$19-1)/$H11)-(สมมติฐาน!$C$26*(Z$19>=สมมติฐาน!$D$26)+$F11*(Z$19>=สมมติฐาน!$D$27)+สมมติฐาน!$C$28*(Z$19>=สมมติฐาน!$D$28)+$G11*(Z$19>=สมมติฐาน!$D$29)) -> -1940000
B26: =B12 -> Pen-test 900,000 | C26: =สมมติฐาน!$C$15+$C12*(C$19>=สมมติฐาน!$C$13)+$D12*(C$19>=$E12)-IF($H12=0,สมมติฐาน!$C$21*C$19,สมมติฐาน!$C$21*((1+$H12)^C$19-1)/$H12)-(สมมติฐาน!$C$26*(C$19>=สมมติฐาน!$D$26)+$F12*(C$19>=สมมติฐาน!$D$27)+สมมติฐาน!$C$28*(C$19>=สมมติฐาน!$D$28)+$G12*(C$19>=สมมติฐาน!$D$29)) -> 1730000 | D26: =สมมติฐาน!$C$15+$C12*(D$19>=สมมติฐาน!$C$13)+$D12*(D$19>=$E12)-IF($H12=0,สมมติฐาน!$C$21*D$19,สมมติฐาน!$C$21*((1+$H12)^D$19-1)/$H12)-(สมมติฐาน!$C$26*(D$19>=สมมติฐาน!$D$26)+$F12*(D$19>=สมมติฐาน!$D$27)+สมมติฐาน!$C$28*(D$19>=สมมติฐาน!$D$28)+$G12*(D$19>=สมมติฐาน!$D$29)) -> 680000 | E26: =สมมติฐาน!$C$15+$C12*(E$19>=สมมติฐาน!$C$13)+$D12*(E$19>=$E12)-IF($H12=0,สมมติฐาน!$C$21*E$19,สมมติฐาน!$C$21*((1+$H12)^E$19-1)/$H12)-(สมมติฐาน!$C$26*(E$19>=สมมติฐาน!$D$26)+$F12*(E$19>=สมมติฐาน!$D$27)+สมมติฐาน!$C$28*(E$19>=สมมติฐาน!$D$28)+$G12*(E$19>=สมมติฐาน!$D$29)) -> 530000 | F26: =สมมติฐาน!$C$15+$C12*(F$19>=สมมติฐาน!$C$13)+$D12*(F$19>=$E12)-IF($H12=0,สมมติฐาน!$C$21*F$19,สมมติฐาน!$C$21*((1+$H12)^F$19-1)/$H12)-(สมมติฐาน!$C$26*(F$19>=สมมติฐาน!$D$26)+$F12*(F$19>=สมมติฐาน!$D$27)+สมมติฐาน!$C$28*(F$19>=สมมติฐาน!$D$28)+$G12*(F$19>=สมมติฐาน!$D$29)) -> 380000 | G26: =สมมติฐาน!$C$15+$C12*(G$19>=สมมติฐาน!$C$13)+$D12*(G$19>=$E12)-IF($H12=0,สมมติฐาน!$C$21*G$19,สมมติฐาน!$C$21*((1+$H12)^G$19-1)/$H12)-(สมมติฐาน!$C$26*(G$19>=สมมติฐาน!$D$26)+$F12*(G$19>=สมมติฐาน!$D$27)+สมมติฐาน!$C$28*(G$19>=สมมติฐาน!$D$28)+$G12*(G$19>=สมมติฐาน!$D$29)) -> 230000 | H26: =สมมติฐาน!$C$15+$C12*(H$19>=สมมติฐาน!$C$13)+$D12*(H$19>=$E12)-IF($H12=0,สมมติฐาน!$C$21*H$19,สมมติฐาน!$C$21*((1+$H12)^H$19-1)/$H12)-(สมมติฐาน!$C$26*(H$19>=สมมติฐาน!$D$26)+$F12*(H$19>=สมมติฐาน!$D$27)+สมมติฐาน!$C$28*(H$19>=สมมติฐาน!$D$28)+$G12*(H$19>=สมมติฐาน!$D$29)) -> -70000 | I26: =สมมติฐาน!$C$15+$C12*(I$19>=สมมติฐาน!$C$13)+$D12*(I$19>=$E12)-IF($H12=0,สมมติฐาน!$C$21*I$19,สมมติฐาน!$C$21*((1+$H12)^I$19-1)/$H12)-(สมมติฐาน!$C$26*(I$19>=สมมติฐาน!$D$26)+$F12*(I$19>=สมมติฐาน!$D$27)+สมมติฐาน!$C$28*(I$19>=สมมติฐาน!$D$28)+$G12*(I$19>=สมมติฐาน!$D$29)) -> 780000 | J26: =สมมติฐาน!$C$15+$C12*(J$19>=สมมติฐาน!$C$13)+$D12*(J$19>=$E12)-IF($H12=0,สมมติฐาน!$C$21*J$19,สมมติฐาน!$C$21*((1+$H12)^J$19-1)/$H12)-(สมมติฐาน!$C$26*(J$19>=สมมติฐาน!$D$26)+$F12*(J$19>=สมมติฐาน!$D$27)+สมมติฐาน!$C$28*(J$19>=สมมติฐาน!$D$28)+$G12*(J$19>=สมมติฐาน!$D$29)) -> 630000 | ... Z26: =สมมติฐาน!$C$15+$C12*(Z$19>=สมมติฐาน!$C$13)+$D12*(Z$19>=$E12)-IF($H12=0,สมมติฐาน!$C$21*Z$19,สมมติฐาน!$C$21*((1+$H12)^Z$19-1)/$H12)-(สมมติฐาน!$C$26*(Z$19>=สมมติฐาน!$D$26)+$F12*(Z$19>=สมมติฐาน!$D$27)+สมมติฐาน!$C$28*(Z$19>=สมมติฐาน!$D$28)+$G12*(Z$19>=สมมติฐาน!$D$29)) -> -2010000
B27: =B13 -> ค่าใช้จ่ายเพิ่ม 2% ต่อเดือน | C27: =สมมติฐาน!$C$15+$C13*(C$19>=สมมติฐาน!$C$13)+$D13*(C$19>=$E13)-IF($H13=0,สมมติฐาน!$C$21*C$19,สมมติฐาน!$C$21*((1+$H13)^C$19-1)/$H13)-(สมมติฐาน!$C$26*(C$19>=สมมติฐาน!$D$26)+$F13*(C$19>=สมมติฐาน!$D$27)+สมมติฐาน!$C$28*(C$19>=สมมติฐาน!$D$28)+$G13*(C$19>=สมมติฐาน!$D$29)) -> 1730000 | D27: =สมมติฐาน!$C$15+$C13*(D$19>=สมมติฐาน!$C$13)+$D13*(D$19>=$E13)-IF($H13=0,สมมติฐาน!$C$21*D$19,สมมติฐาน!$C$21*((1+$H13)^D$19-1)/$H13)-(สมมติฐาน!$C$26*(D$19>=สมมติฐาน!$D$26)+$F13*(D$19>=สมมติฐาน!$D$27)+สมมติฐาน!$C$28*(D$19>=สมมติฐาน!$D$28)+$G13*(D$19>=สมมติฐาน!$D$29)) -> 1127000 | E27: =สมมติฐาน!$C$15+$C13*(E$19>=สมมติฐาน!$C$13)+$D13*(E$19>=$E13)-IF($H13=0,สมมติฐาน!$C$21*E$19,สมมติฐาน!$C$21*((1+$H13)^E$19-1)/$H13)-(สมมติฐาน!$C$26*(E$19>=สมมติฐาน!$D$26)+$F13*(E$19>=สมมติฐาน!$D$27)+สมมติฐาน!$C$28*(E$19>=สมมติฐาน!$D$28)+$G13*(E$19>=สมมติฐาน!$D$29)) -> 970940 | F27: =สมมติฐาน!$C$15+$C13*(F$19>=สมมติฐาน!$C$13)+$D13*(F$19>=$E13)-IF($H13=0,สมมติฐาน!$C$21*F$19,สมมติฐาน!$C$21*((1+$H13)^F$19-1)/$H13)-(สมมติฐาน!$C$26*(F$19>=สมมติฐาน!$D$26)+$F13*(F$19>=สมมติฐาน!$D$27)+สมมติฐาน!$C$28*(F$19>=สมมติฐาน!$D$28)+$G13*(F$19>=สมมติฐาน!$D$29)) -> 811758.8 | G27: =สมมติฐาน!$C$15+$C13*(G$19>=สมมติฐาน!$C$13)+$D13*(G$19>=$E13)-IF($H13=0,สมมติฐาน!$C$21*G$19,สมมติฐาน!$C$21*((1+$H13)^G$19-1)/$H13)-(สมมติฐาน!$C$26*(G$19>=สมมติฐาน!$D$26)+$F13*(G$19>=สมมติฐาน!$D$27)+สมมติฐาน!$C$28*(G$19>=สมมติฐาน!$D$28)+$G13*(G$19>=สมมติฐาน!$D$29)) -> 649393.98 | H27: =สมมติฐาน!$C$15+$C13*(H$19>=สมมติฐาน!$C$13)+$D13*(H$19>=$E13)-IF($H13=0,สมมติฐาน!$C$21*H$19,สมมติฐาน!$C$21*((1+$H13)^H$19-1)/$H13)-(สมมติฐาน!$C$26*(H$19>=สมมติฐาน!$D$26)+$F13*(H$19>=สมมติฐาน!$D$27)+สมมติฐาน!$C$28*(H$19>=สมมติฐาน!$D$28)+$G13*(H$19>=สมมติฐาน!$D$29)) -> 333781.86 | I27: =สมมติฐาน!$C$15+$C13*(I$19>=สมมติฐาน!$C$13)+$D13*(I$19>=$E13)-IF($H13=0,สมมติฐาน!$C$21*I$19,สมมติฐาน!$C$21*((1+$H13)^I$19-1)/$H13)-(สมมติฐาน!$C$26*(I$19>=สมมติฐาน!$D$26)+$F13*(I$19>=สมมติฐาน!$D$27)+สมมติฐาน!$C$28*(I$19>=สมมติฐาน!$D$28)+$G13*(I$19>=สมมติฐาน!$D$29)) -> 1164857.5 | J27: =สมมติฐาน!$C$15+$C13*(J$19>=สมมติฐาน!$C$13)+$D13*(J$19>=$E13)-IF($H13=0,สมมติฐาน!$C$21*J$19,สมมติฐาน!$C$21*((1+$H13)^J$19-1)/$H13)-(สมมติฐาน!$C$26*(J$19>=สมมติฐาน!$D$26)+$F13*(J$19>=สมมติฐาน!$D$27)+สมมติฐาน!$C$28*(J$19>=สมมติฐาน!$D$28)+$G13*(J$19>=สมมติฐาน!$D$29)) -> 992554.64 | ... Z27: =สมมติฐาน!$C$15+$C13*(Z$19>=สมมติฐาน!$C$13)+$D13*(Z$19>=$E13)-IF($H13=0,สมมติฐาน!$C$21*Z$19,สมมติฐาน!$C$21*((1+$H13)^Z$19-1)/$H13)-(สมมติฐาน!$C$26*(Z$19>=สมมติฐาน!$D$26)+$F13*(Z$19>=สมมติฐาน!$D$27)+สมมติฐาน!$C$28*(Z$19>=สมมติฐาน!$D$28)+$G13*(Z$19>=สมมติฐาน!$D$29)) -> -2523279.4
B28: =B14 -> ฮาร์ดแวร์ 400,000 | C28: =สมมติฐาน!$C$15+$C14*(C$19>=สมมติฐาน!$C$13)+$D14*(C$19>=$E14)-IF($H14=0,สมมติฐาน!$C$21*C$19,สมมติฐาน!$C$21*((1+$H14)^C$19-1)/$H14)-(สมมติฐาน!$C$26*(C$19>=สมมติฐาน!$D$26)+$F14*(C$19>=สมมติฐาน!$D$27)+สมมติฐาน!$C$28*(C$19>=สมมติฐาน!$D$28)+$G14*(C$19>=สมมติฐาน!$D$29)) -> 1730000 | D28: =สมมติฐาน!$C$15+$C14*(D$19>=สมมติฐาน!$C$13)+$D14*(D$19>=$E14)-IF($H14=0,สมมติฐาน!$C$21*D$19,สมมติฐาน!$C$21*((1+$H14)^D$19-1)/$H14)-(สมมติฐาน!$C$26*(D$19>=สมมติฐาน!$D$26)+$F14*(D$19>=สมมติฐาน!$D$27)+สมมติฐาน!$C$28*(D$19>=สมมติฐาน!$D$28)+$G14*(D$19>=สมมติฐาน!$D$29)) -> 1130000 | E28: =สมมติฐาน!$C$15+$C14*(E$19>=สมมติฐาน!$C$13)+$D14*(E$19>=$E14)-IF($H14=0,สมมติฐาน!$C$21*E$19,สมมติฐาน!$C$21*((1+$H14)^E$19-1)/$H14)-(สมมติฐาน!$C$26*(E$19>=สมมติฐาน!$D$26)+$F14*(E$19>=สมมติฐาน!$D$27)+สมมติฐาน!$C$28*(E$19>=สมมติฐาน!$D$28)+$G14*(E$19>=สมมติฐาน!$D$29)) -> 980000 | F28: =สมมติฐาน!$C$15+$C14*(F$19>=สมมติฐาน!$C$13)+$D14*(F$19>=$E14)-IF($H14=0,สมมติฐาน!$C$21*F$19,สมมติฐาน!$C$21*((1+$H14)^F$19-1)/$H14)-(สมมติฐาน!$C$26*(F$19>=สมมติฐาน!$D$26)+$F14*(F$19>=สมมติฐาน!$D$27)+สมมติฐาน!$C$28*(F$19>=สมมติฐาน!$D$28)+$G14*(F$19>=สมมติฐาน!$D$29)) -> 830000 | G28: =สมมติฐาน!$C$15+$C14*(G$19>=สมมติฐาน!$C$13)+$D14*(G$19>=$E14)-IF($H14=0,สมมติฐาน!$C$21*G$19,สมมติฐาน!$C$21*((1+$H14)^G$19-1)/$H14)-(สมมติฐาน!$C$26*(G$19>=สมมติฐาน!$D$26)+$F14*(G$19>=สมมติฐาน!$D$27)+สมมติฐาน!$C$28*(G$19>=สมมติฐาน!$D$28)+$G14*(G$19>=สมมติฐาน!$D$29)) -> 680000 | H28: =สมมติฐาน!$C$15+$C14*(H$19>=สมมติฐาน!$C$13)+$D14*(H$19>=$E14)-IF($H14=0,สมมติฐาน!$C$21*H$19,สมมติฐาน!$C$21*((1+$H14)^H$19-1)/$H14)-(สมมติฐาน!$C$26*(H$19>=สมมติฐาน!$D$26)+$F14*(H$19>=สมมติฐาน!$D$27)+สมมติฐาน!$C$28*(H$19>=สมมติฐาน!$D$28)+$G14*(H$19>=สมมติฐาน!$D$29)) -> 380000 | I28: =สมมติฐาน!$C$15+$C14*(I$19>=สมมติฐาน!$C$13)+$D14*(I$19>=$E14)-IF($H14=0,สมมติฐาน!$C$21*I$19,สมมติฐาน!$C$21*((1+$H14)^I$19-1)/$H14)-(สมมติฐาน!$C$26*(I$19>=สมมติฐาน!$D$26)+$F14*(I$19>=สมมติฐาน!$D$27)+สมมติฐาน!$C$28*(I$19>=สมมติฐาน!$D$28)+$G14*(I$19>=สมมติฐาน!$D$29)) -> 1230000 | J28: =สมมติฐาน!$C$15+$C14*(J$19>=สมมติฐาน!$C$13)+$D14*(J$19>=$E14)-IF($H14=0,สมมติฐาน!$C$21*J$19,สมมติฐาน!$C$21*((1+$H14)^J$19-1)/$H14)-(สมมติฐาน!$C$26*(J$19>=สมมติฐาน!$D$26)+$F14*(J$19>=สมมติฐาน!$D$27)+สมมติฐาน!$C$28*(J$19>=สมมติฐาน!$D$28)+$G14*(J$19>=สมมติฐาน!$D$29)) -> 1080000 | ... Z28: =สมมติฐาน!$C$15+$C14*(Z$19>=สมมติฐาน!$C$13)+$D14*(Z$19>=$E14)-IF($H14=0,สมมติฐาน!$C$21*Z$19,สมมติฐาน!$C$21*((1+$H14)^Z$19-1)/$H14)-(สมมติฐาน!$C$26*(Z$19>=สมมติฐาน!$D$26)+$F14*(Z$19>=สมมติฐาน!$D$27)+สมมติฐาน!$C$28*(Z$19>=สมมติฐาน!$D$28)+$G14*(Z$19>=สมมติฐาน!$D$29)) -> -1720000
B29: =B15 -> Pen-test 900,000 + งวดที่ 2 ล่าช้า 1 เดือน | C29: =สมมติฐาน!$C$15+$C15*(C$19>=สมมติฐาน!$C$13)+$D15*(C$19>=$E15)-IF($H15=0,สมมติฐาน!$C$21*C$19,สมมติฐาน!$C$21*((1+$H15)^C$19-1)/$H15)-(สมมติฐาน!$C$26*(C$19>=สมมติฐาน!$D$26)+$F15*(C$19>=สมมติฐาน!$D$27)+สมมติฐาน!$C$28*(C$19>=สมมติฐาน!$D$28)+$G15*(C$19>=สมมติฐาน!$D$29)) -> 1730000 | D29: =สมมติฐาน!$C$15+$C15*(D$19>=สมมติฐาน!$C$13)+$D15*(D$19>=$E15)-IF($H15=0,สมมติฐาน!$C$21*D$19,สมมติฐาน!$C$21*((1+$H15)^D$19-1)/$H15)-(สมมติฐาน!$C$26*(D$19>=สมมติฐาน!$D$26)+$F15*(D$19>=สมมติฐาน!$D$27)+สมมติฐาน!$C$28*(D$19>=สมมติฐาน!$D$28)+$G15*(D$19>=สมมติฐาน!$D$29)) -> 680000 | E29: =สมมติฐาน!$C$15+$C15*(E$19>=สมมติฐาน!$C$13)+$D15*(E$19>=$E15)-IF($H15=0,สมมติฐาน!$C$21*E$19,สมมติฐาน!$C$21*((1+$H15)^E$19-1)/$H15)-(สมมติฐาน!$C$26*(E$19>=สมมติฐาน!$D$26)+$F15*(E$19>=สมมติฐาน!$D$27)+สมมติฐาน!$C$28*(E$19>=สมมติฐาน!$D$28)+$G15*(E$19>=สมมติฐาน!$D$29)) -> 530000 | F29: =สมมติฐาน!$C$15+$C15*(F$19>=สมมติฐาน!$C$13)+$D15*(F$19>=$E15)-IF($H15=0,สมมติฐาน!$C$21*F$19,สมมติฐาน!$C$21*((1+$H15)^F$19-1)/$H15)-(สมมติฐาน!$C$26*(F$19>=สมมติฐาน!$D$26)+$F15*(F$19>=สมมติฐาน!$D$27)+สมมติฐาน!$C$28*(F$19>=สมมติฐาน!$D$28)+$G15*(F$19>=สมมติฐาน!$D$29)) -> 380000 | G29: =สมมติฐาน!$C$15+$C15*(G$19>=สมมติฐาน!$C$13)+$D15*(G$19>=$E15)-IF($H15=0,สมมติฐาน!$C$21*G$19,สมมติฐาน!$C$21*((1+$H15)^G$19-1)/$H15)-(สมมติฐาน!$C$26*(G$19>=สมมติฐาน!$D$26)+$F15*(G$19>=สมมติฐาน!$D$27)+สมมติฐาน!$C$28*(G$19>=สมมติฐาน!$D$28)+$G15*(G$19>=สมมติฐาน!$D$29)) -> 230000 | H29: =สมมติฐาน!$C$15+$C15*(H$19>=สมมติฐาน!$C$13)+$D15*(H$19>=$E15)-IF($H15=0,สมมติฐาน!$C$21*H$19,สมมติฐาน!$C$21*((1+$H15)^H$19-1)/$H15)-(สมมติฐาน!$C$26*(H$19>=สมมติฐาน!$D$26)+$F15*(H$19>=สมมติฐาน!$D$27)+สมมติฐาน!$C$28*(H$19>=สมมติฐาน!$D$28)+$G15*(H$19>=สมมติฐาน!$D$29)) -> -70000 | I29: =สมมติฐาน!$C$15+$C15*(I$19>=สมมติฐาน!$C$13)+$D15*(I$19>=$E15)-IF($H15=0,สมมติฐาน!$C$21*I$19,สมมติฐาน!$C$21*((1+$H15)^I$19-1)/$H15)-(สมมติฐาน!$C$26*(I$19>=สมมติฐาน!$D$26)+$F15*(I$19>=สมมติฐาน!$D$27)+สมมติฐาน!$C$28*(I$19>=สมมติฐาน!$D$28)+$G15*(I$19>=สมมติฐาน!$D$29)) -> -220000 | J29: =สมมติฐาน!$C$15+$C15*(J$19>=สมมติฐาน!$C$13)+$D15*(J$19>=$E15)-IF($H15=0,สมมติฐาน!$C$21*J$19,สมมติฐาน!$C$21*((1+$H15)^J$19-1)/$H15)-(สมมติฐาน!$C$26*(J$19>=สมมติฐาน!$D$26)+$F15*(J$19>=สมมติฐาน!$D$27)+สมมติฐาน!$C$28*(J$19>=สมมติฐาน!$D$28)+$G15*(J$19>=สมมติฐาน!$D$29)) -> 630000 | ... Z29: =สมมติฐาน!$C$15+$C15*(Z$19>=สมมติฐาน!$C$13)+$D15*(Z$19>=$E15)-IF($H15=0,สมมติฐาน!$C$21*Z$19,สมมติฐาน!$C$21*((1+$H15)^Z$19-1)/$H15)-(สมมติฐาน!$C$26*(Z$19>=สมมติฐาน!$D$26)+$F15*(Z$19>=สมมติฐาน!$D$27)+สมมติฐาน!$C$28*(Z$19>=สมมติฐาน!$D$28)+$G15*(Z$19>=สมมติฐาน!$D$29)) -> -2010000
B32: ตัวช่วย: ธงเงินสดติดลบ (1 = ติดลบ)
B33: สถานการณ์ | C33: 1 | D33: 2 | E33: 3 | F33: 4 | G33: 5 | H33: 6 | I33: 7 | J33: 8 | K33: 9 | L33: 10 | M33: 11 | N33: 12 | O33: 13 | P33: 14 | Q33: 15 | R33: 16 | S33: 17 | T33: 18 | U33: 19 | V33: 20 | W33: 21 | X33: 22 | Y33: 23 | Z33: 24
B34: =B6 -> ฐาน (ตามสมมติฐาน) | C34: =IF(C20<0,1,0) -> 0 | D34: =IF(D20<0,1,0) -> 0 | E34: =IF(E20<0,1,0) -> 0 | F34: =IF(F20<0,1,0) -> 0 | G34: =IF(G20<0,1,0) -> 0 | H34: =IF(H20<0,1,0) -> 0 | I34: =IF(I20<0,1,0) -> 0 | J34: =IF(J20<0,1,0) -> 0 | ... Z34: =IF(Z20<0,1,0) -> 1
B35: =B7 -> ได้เฉพาะงวดที่ 1 (ไม่ปลดงวดที่ 2) | C35: =IF(C21<0,1,0) -> 0 | D35: =IF(D21<0,1,0) -> 0 | E35: =IF(E21<0,1,0) -> 0 | F35: =IF(F21<0,1,0) -> 0 | G35: =IF(G21<0,1,0) -> 0 | H35: =IF(H21<0,1,0) -> 0 | I35: =IF(I21<0,1,0) -> 0 | J35: =IF(J21<0,1,0) -> 0 | ... Z35: =IF(Z21<0,1,0) -> 1
B36: =B8 -> งวดที่ 2 ล่าช้า 1 เดือน | C36: =IF(C22<0,1,0) -> 0 | D36: =IF(D22<0,1,0) -> 0 | E36: =IF(E22<0,1,0) -> 0 | F36: =IF(F22<0,1,0) -> 0 | G36: =IF(G22<0,1,0) -> 0 | H36: =IF(H22<0,1,0) -> 0 | I36: =IF(I22<0,1,0) -> 0 | J36: =IF(J22<0,1,0) -> 0 | ... Z36: =IF(Z22<0,1,0) -> 1
B37: =B9 -> งวดที่ 2 ล่าช้า 2 เดือน | C37: =IF(C23<0,1,0) -> 0 | D37: =IF(D23<0,1,0) -> 0 | E37: =IF(E23<0,1,0) -> 0 | F37: =IF(F23<0,1,0) -> 0 | G37: =IF(G23<0,1,0) -> 0 | H37: =IF(H23<0,1,0) -> 0 | I37: =IF(I23<0,1,0) -> 0 | J37: =IF(J23<0,1,0) -> 0 | ... Z37: =IF(Z23<0,1,0) -> 1
B38: =B10 -> Pen-test 700,000 | C38: =IF(C24<0,1,0) -> 0 | D38: =IF(D24<0,1,0) -> 0 | E38: =IF(E24<0,1,0) -> 0 | F38: =IF(F24<0,1,0) -> 0 | G38: =IF(G24<0,1,0) -> 0 | H38: =IF(H24<0,1,0) -> 0 | I38: =IF(I24<0,1,0) -> 0 | J38: =IF(J24<0,1,0) -> 0 | ... Z38: =IF(Z24<0,1,0) -> 1
B39: =B11 -> Pen-test 830,000 (เงินสดเดือน 6 ≈ 0) | C39: =IF(C25<0,1,0) -> 0 | D39: =IF(D25<0,1,0) -> 0 | E39: =IF(E25<0,1,0) -> 0 | F39: =IF(F25<0,1,0) -> 0 | G39: =IF(G25<0,1,0) -> 0 | H39: =IF(H25<0,1,0) -> 0 | I39: =IF(I25<0,1,0) -> 0 | J39: =IF(J25<0,1,0) -> 0 | ... Z39: =IF(Z25<0,1,0) -> 1
B40: =B12 -> Pen-test 900,000 | C40: =IF(C26<0,1,0) -> 0 | D40: =IF(D26<0,1,0) -> 0 | E40: =IF(E26<0,1,0) -> 0 | F40: =IF(F26<0,1,0) -> 0 | G40: =IF(G26<0,1,0) -> 0 | H40: =IF(H26<0,1,0) -> 1 | I40: =IF(I26<0,1,0) -> 0 | J40: =IF(J26<0,1,0) -> 0 | ... Z40: =IF(Z26<0,1,0) -> 1
B41: =B13 -> ค่าใช้จ่ายเพิ่ม 2% ต่อเดือน | C41: =IF(C27<0,1,0) -> 0 | D41: =IF(D27<0,1,0) -> 0 | E41: =IF(E27<0,1,0) -> 0 | F41: =IF(F27<0,1,0) -> 0 | G41: =IF(G27<0,1,0) -> 0 | H41: =IF(H27<0,1,0) -> 0 | I41: =IF(I27<0,1,0) -> 0 | J41: =IF(J27<0,1,0) -> 0 | ... Z41: =IF(Z27<0,1,0) -> 1
B42: =B14 -> ฮาร์ดแวร์ 400,000 | C42: =IF(C28<0,1,0) -> 0 | D42: =IF(D28<0,1,0) -> 0 | E42: =IF(E28<0,1,0) -> 0 | F42: =IF(F28<0,1,0) -> 0 | G42: =IF(G28<0,1,0) -> 0 | H42: =IF(H28<0,1,0) -> 0 | I42: =IF(I28<0,1,0) -> 0 | J42: =IF(J28<0,1,0) -> 0 | ... Z42: =IF(Z28<0,1,0) -> 1
B43: =B15 -> Pen-test 900,000 + งวดที่ 2 ล่าช้า 1 เดือน | C43: =IF(C29<0,1,0) -> 0 | D43: =IF(D29<0,1,0) -> 0 | E43: =IF(E29<0,1,0) -> 0 | F43: =IF(F29<0,1,0) -> 0 | G43: =IF(G29<0,1,0) -> 0 | H43: =IF(H29<0,1,0) -> 1 | I43: =IF(I29<0,1,0) -> 1 | J43: =IF(J29<0,1,0) -> 0 | ... Z43: =IF(Z29<0,1,0) -> 1
